Workbook
Name CalendarYear: [1]January!$K$5
Name ColumnTitleRegion1..H12.6: #REF!
Name ColumnTitleRegion1..H12.6: #REF!
Name ColumnTitleRegion1..H12.6: #REF!
Name ColumnTitleRegion1..H12.6: #REF!
Name ColumnTitleRegion1..H12.6: #REF!
Name ColumnTitleRegion1..H12.6: #REF!
Name ColumnTitleRegion2..C14.6: #REF!
Name ColumnTitleRegion2..C14.6: #REF!
Name ColumnTitleRegion2..C14.6: #REF!
Name ColumnTitleRegion2..C14.6: #REF!
Name ColumnTitleRegion2..C14.6: #REF!
Name ColumnTitleRegion2..C14.6: #REF!
Name DaysAndWeeks: {0,1,2,3,4,5,6} + {0;1;2;3;4;5}*7
Name Raw_data: OFFSET([2]로데이터!$A$1,0,0,COUNTA([2]로데이터!$A:$A),COUNTA([2]로데이터!$1:$1))
Name WeekStart: [1]January!$L$5

Sheet Price Jun_Water Purifier
C2: Promotion Price June 2026
E3: Outright + 2Y Service | I3: Service Cycle | J3: Subscription Fee
J4: Contract 5Y | AB4: Contract 7Y
J5: VISIT | S5: SELF | AB5: VISIT | AK5: SELF
B6: Classification | C6: Model | E6: Visit | F6: Discount 10% | G6: Self | H6: Discount 10% | J6: Visit 5Y Monthly price | K6: Total Month | L6: Normal total price | M6: Cost | N6: Promotion Jun (6 รอบบิล) | O6: Disc.50% (12 รอบบิล) | P6: Disc.50% (18 รอบบิล) | Q6: Promotion Net | R6: Disc | S6: Self 5Y Monthly price | T6: Total Month | U6: Normal total price | V6: Cost | W6: Promotion Jun (6 รอบบิล) | X6: Disc.50% (12 รอบบิล) | Y6: Disc.50% (18 รอบบิล) | Z6: Promotion Net | AA6: Disc | AB6: Visit 7Y Monthly price | AC6: Total Month | AD6: Normal total price | AE6: Cost | AF6: Promotion Jun (6 รอบบิล) | AG6: Disc.50% (12 รอบบิล) | AH6: Disc.50% (18 รอบบิล) | AI6: Promotion Net | AJ6: Disc | AK6: Self 7Y Monthly price | AL6: Total Month | AM6: Normal total price | AN6: Cost | AO6: Promotion Jun (6 รอบบิล) | AP6: Disc.50% (12 รอบบิล) | AQ6: Disc.50% (18 รอบบิล) | AR6: Promotion Net | AS6: Disc
B7: WP | C7: WD516AN.ACNPLMT | D7: ATOM 4D+ Calming Navy | E7: 37900 | F7: =ROUNDDOWN(E7*0.9,0) -> 34110 | G7: 34900 | H7: =ROUNDDOWN(G7*0.9,0) -> 31410 | I7: 6M | J7: 799 | K7: 60 | L7: =K7*J7 -> 47940 | N7: 149 | Q7: =(N7*6)+(J7*54) -> 44040 | R7: =L7-Q7 -> 3900 | S7: 699 | T7: 60 | U7: =T7*S7 -> 41940 | W7: 149 | Z7: =(W7*6)+(S7*54) -> 38640 | AA7: =U7-Z7 -> 3300 | AB7: 599 | AC7: 84 | AD7: =AC7*AB7 -> 50316 | AF7: 149 | AI7: =(AF7*6)+(AB7*78) -> 47616 | AJ7: =AD7-AI7 -> 2700 | AK7: 499 | AL7: 84 | AM7: =AL7*AK7 -> 41916 | AO7: 149 | AR7: =(AO7*6)+(AK7*78) -> 39816 | AS7: =AM7-AR7 -> 2100
C8: WD516AN.AEWPLMT | D8: ATOM 4D+ Essense White | E8: 37900 | F8: =ROUNDDOWN(E8*0.9,0) -> 34110 | G8: 34900 | H8: =ROUNDDOWN(G8*0.9,0) -> 31410 | I8: 6M | J8: 799 | K8: 60 | L8: =K8*J8 -> 47940 | N8: 149 | Q8: =(N8*6)+(J8*54) -> 44040 | R8: =L8-Q8 -> 3900 | S8: 699 | T8: 60 | U8: =T8*S8 -> 41940 | W8: 149 | Z8: =(W8*6)+(S8*54) -> 38640 | AA8: =U8-Z8 -> 3300 | AB8: 599 | AC8: 84 | AD8: =AC8*AB8 -> 50316 | AF8: 149 | AI8: =(AF8*6)+(AB8*78) -> 47616 | AJ8: =AD8-AI8 -> 2700 | AK8: 499 | AL8: 84 | AM8: =AL8*AK8 -> 41916 | AO8: 149 | AR8: =(AO8*6)+(AK8*78) -> 39816 | AS8: =AM8-AR8 -> 2100
C9: WD516AN.ASLPLMT | D9: ATOM 4D+ Silver | E9: 37900 | F9: =ROUNDDOWN(E9*0.9,0) -> 34110 | G9: 34900 | H9: =ROUNDDOWN(G9*0.9,0) -> 31410 | I9: 6M | J9: 799 | K9: 60 | L9: =K9*J9 -> 47940 | N9: 149 | Q9: =(N9*6)+(J9*54) -> 44040 | R9: =L9-Q9 -> 3900 | S9: 699 | T9: 60 | U9: =T9*S9 -> 41940 | W9: 149 | Z9: =(W9*6)+(S9*54) -> 38640 | AA9: =U9-Z9 -> 3300 | AB9: 599 | AC9: 84 | AD9: =AC9*AB9 -> 50316 | AF9: 149 | AI9: =(AF9*6)+(AB9*78) -> 47616 | AJ9: =AD9-AI9 -> 2700 | AK9: 499 | AL9: 84 | AM9: =AL9*AK9 -> 41916 | AO9: 149 | AR9: =(AO9*6)+(AK9*78) -> 39816 | AS9: =AM9-AR9 -> 2100
C10: WD518AN.ABGPLMT | D10: ATOM V Calming Beige | E10: 37900 | F10: =ROUNDDOWN(E10*0.9,0) -> 34110 | G10: 34900 | H10: =ROUNDDOWN(G10*0.9,0) -> 31410 | I10: 6M | J10: 799 | K10: 60 | L10: =K10*J10 -> 47940 | N10: 149 | Q10: =(N10*6)+(J10*54) -> 44040 | R10: =L10-Q10 -> 3900 | S10: 699 | T10: 60 | U10: =T10*S10 -> 41940 | W10: 149 | Z10: =(W10*6)+(S10*54) -> 38640 | AA10: =U10-Z10 -> 3300 | AB10: 599 | AC10: 84 | AD10: =AC10*AB10 -> 50316 | AF10: 149 | AI10: =(AF10*6)+(AB10*78) -> 47616 | AJ10: =AD10-AI10 -> 2700 | AK10: 499 | AL10: 84 | AM10: =AL10*AK10 -> 41916 | AO10: 149 | AR10: =(AO10*6)+(AK10*78) -> 39816 | AS10: =AM10-AR10 -> 2100
C11: WD518AN.AWHPLMT | D11: ATOM V Calming Cream White | E11: 37900 | F11: =ROUNDDOWN(E11*0.9,0) -> 34110 | G11: 34900 | H11: =ROUNDDOWN(G11*0.9,0) -> 31410 | I11: 6M | J11: 799 | K11: 60 | L11: =K11*J11 -> 47940 | N11: 149 | Q11: =(N11*6)+(J11*54) -> 44040 | R11: =L11-Q11 -> 3900 | S11: 699 | T11: 60 | U11: =T11*S11 -> 41940 | W11: 149 | Z11: =(W11*6)+(S11*54) -> 38640 | AA11: =U11-Z11 -> 3300 | AB11: 599 | AC11: 84 | AD11: =AC11*AB11 -> 50316 | AF11: 149 | AI11: =(AF11*6)+(AB11*78) -> 47616 | AJ11: =AD11-AI11 -> 2700 | AK11: 499 | AL11: 84 | AM11: =AL11*AK11 -> 41916 | AO11: 149 | AR11: =(AO11*6)+(AK11*78) -> 39816 | AS11: =AM11-AR11 -> 2100
C12: WD518AN.ACGPLMT | D12: ATOM V Cream Gray | E12: 37900 | F12: =ROUNDDOWN(E12*0.9,0) -> 34110 | G12: 34900 | H12: =ROUNDDOWN(G12*0.9,0) -> 31410 | I12: 6M | J12: 799 | K12: 60 | L12: =K12*J12 -> 47940 | N12: 149 | Q12: =(N12*6)+(J12*54) -> 44040 | R12: =L12-Q12 -> 3900 | S12: 699 | T12: 60 | U12: =T12*S12 -> 41940 | W12: 149 | Z12: =(W12*6)+(S12*54) -> 38640 | AA12: =U12-Z12 -> 3300 | AB12: 599 | AC12: 84 | AD12: =AC12*AB12 -> 50316 | AF12: 149 | AI12: =(AF12*6)+(AB12*78) -> 47616 | AJ12: =AD12-AI12 -> 2700 | AK12: 499 | AL12: 84 | AM12: =AL12*AK12 -> 41916 | AO12: 149 | AR12: =(AO12*6)+(AK12*78) -> 39816 | AS12: =AM12-AR12 -> 2100
C13: WD110MN.ABGPLMT | D13: MX Calming Beige | E13: 0 | F13: =ROUNDDOWN(E13*0.9,0) -> 0 | G13: 0 | H13: =ROUNDDOWN(G13*0.9,0) -> 0 | I13: 6M | J13: 549 | K13: 60 | L13: =K13*J13 -> 32940 | N13: 99 | Q13: =(N13*6)+(J13*54) -> 30240 | R13: =L13-Q13 -> 2700 | S13: 499 | T13: 60 | U13: =T13*S13 -> 29940 | W13: 99 | Z13: =(W13*6)+(S13*54) -> 27540 | AA13: =U13-Z13 -> 2400 | AB13: 449 | AC13: 84 | AD13: =AC13*AB13 -> 37716 | AF13: 99 | AI13: =(AF13*6)+(AB13*78) -> 35616 | AJ13: =AD13-AI13 -> 2100 | AK13: 399 | AL13: 84 | AM13: =AL13*AK13 -> 33516 | AO13: 99 | AR13: =(AO13*6)+(AK13*78) -> 31716 | AS13: =AM13-AR13 -> 1800
C14: WS510SN.AWHPLMT | D14: Stand Water Purifier White | E14: 0 | F14: =ROUNDDOWN(E14*0.9,0) -> 0 | G14: 0 | H14: =ROUNDDOWN(G14*0.9,0) -> 0 | I14: 3M | J14: =1049+50 -> 1099 | K14: 60 | L14: =K14*J14 -> 65940 | N14: 149 | Q14: =(N14*6)+(J14*54) -> 60240 | R14: =L14-Q14 -> 5700 | U14: =T14*S14 -> 0 | Z14: =(W14*6)+(S14*54) -> 0 | AA14: =U14-Z14 -> 0 | AB14: =849+50 -> 899 | AC14: 84 | AD14: =AC14*AB14 -> 75516 | AF14: 149 | AI14: =(AF14*6)+(AB14*78) -> 71016 | AJ14: =AD14-AI14 -> 4500 | AM14: =AL14*AK14 -> 0 | AO14: -

Sheet REF, WM, Styler,DW,MWO
E1: Promotion Price June 2026
K3: Contract 5Y | AQ3: Contract 6Y
K4: VISIT | AB4: SELF | AQ4: VISIT | BH4: SELF
C5: Classification | D5: Remark | E5: Model | G5: PTO model Promotion Free Gift | H5: Product (1) | I5: Product (2) | J5: Service Cycle | K5: Visit 5Y Monthly price | L5: Total Month | M5: Normal total price | N5: Cost | O5: Promotion Jun | P5: Promotion | Q5: Disc.50% (3 รอบบิล) | R5: Disc.50% (2 รอบบิล) | S5: Disc.50% (5 รอบบิล) | T5: Disc.50% (6 รอบบิล) | U5: Disc.50% (11 รอบบิล) | V5: Disc.50% (12 รอบบิล) | W5: Promotion Jun (1 รอบบิล) | X5: Promotion Jun (3 รอบบิล) | Y5: Promotion Jun (6 รอบบิล) | Z5: Promotion Net | AA5: Disc from Normal | AB5: Self 5Y Monthly price | AC5: Total Month | AD5: Normal total price | AE5: Cost | AF5: Promotion Jun | AG5: Promotion | AH5: Disc.50% (5 รอบบิล) | AI5: Disc.50% (6 รอบบิล) | AJ5: Disc.50% (11 รอบบิล) | AK5: Disc.50% (12 รอบบิล) | AL5: Promotion Jun (1 รอบบิล) | AM5: Promotion Jun (3 รอบบิล) | AN5: Promotion Jun (6 รอบบิล) | AO5: Promotion Net | AP5: Disc from Normal | AQ5: Visit 6Y Monthly price | AR5: Total Month | AS5: Normal total price | AT5: Cost | AU5: Promotion Jun | AV5: Promotion | AW5: Disc.50% (3 รอบบิล) | AX5: Disc.50% (2 รอบบิล) | AY5: Disc.50% (5 รอบบิล) | AZ5: Disc.50% (6 รอบบิล) | BA5: Disc.50% (11 รอบบิล) | BB5: Disc.50% (12 รอบบิล) | BC5: Promotion Jun (1 รอบบิล) | BD5: Promotion Jun (3 รอบบิล) | BE5: Promotion Jun (6 รอบบิล) | BF5: Promotion Net | BG5: Disc from Normal | BH5: Self 6Y Monthly price | BI5: Total Month | BJ5: Normal total price | BK5: Cost | BL5: Promotion Jun | BM5: Promotion | BN5: Disc.50% (5 รอบบิล) | BO5: Disc.50% (6 รอบบิล) | BP5: Disc.50% (11 รอบบิล) | BQ5: Disc.50% (12 รอบบิล) | BR5: Promotion Jun (1 รอบบิล) | BS5: Promotion Jun (3 รอบบิล) | BT5: Promotion Jun (6 รอบบิล) | BU5: Promotion Net | BV5: Disc from Normal
C6: REF | E6: GC-X257CMEW.ATEPLMT | F6: Side-By-Side /SIZE : 22.4 คิว/ 635 ลิตร | J6: 24M | K6: =1199+50 -> 1249 | L6: 60 | M6: =L6*K6 -> 74940 | P6: =MIN(K6,O6)*57 -> 71193 | R6: =ROUNDDOWN(MIN(K6,O6)*0.5,0) -> 624 | W6: 149 | Z6: =P6+(W6*1)+(R6*2) -> 72590 | AA6: =M6-Z6 -> 2350 | AQ6: =999+50 -> 1049 | AR6: 72 | AS6: =AR6*AQ6 -> 75528 | AV6: =MIN(AQ6,AU6)*69 -> 72381 | AX6: =ROUNDDOWN(MIN(AQ6,AU6)*0.5,0) -> 524 | BC6: 149 | BF6: =AV6+(BC6*1)+(AX6*2) -> 73578 | BG6: =AS6-BF6 -> 1950
E7: GC-J257SQZW.AEPPLMT | F7: Side-By-Side /Door in Door/22.4Q/ 635 ลิตร | J7: 24M | K7: =949+50+50 -> 1049 | L7: 60 | M7: =L7*K7 -> 62940 | P7: =MIN(K7,O7)*57 -> 59793 | R7: =ROUNDDOWN(MIN(K7,O7)*0.5,0) -> 524 | W7: 149 | Z7: =P7+(W7*1)+(R7*2) -> 60990 | AA7: =M7-Z7 -> 1950 | AQ7: =799+50+50 -> 899 | AR7: 72 | AS7: =AR7*AQ7 -> 64728 | AV7: =MIN(AQ7,AU7)*69 -> 62031 | AX7: =ROUNDDOWN(MIN(AQ7,AU7)*0.5,0) -> 449 | BC7: 149 | BF7: =AV7+(BC7*1)+(AX7*2) -> 63078 | BG7: =AS7-BF7 -> 1650
E8: GC-L257SFZW.APYPLMT | F8: Side-By-Side/ 22.4 Q/ 635 ลิตร | J8: 24M | K8: 849 | L8: 60 | M8: =L8*K8 -> 50940 | P8: =MIN(K8,O8)*57 -> 48393 | Q8: =ROUNDDOWN(MIN(K8,O8)*0.5,0) -> 424 | Z8: =P8+(Q8*3) -> 49665 | AA8: =M8-Z8 -> 1275 | AQ8: 749 | AR8: 72 | AS8: =AR8*AQ8 -> 53928 | AV8: =MIN(AQ8,AU8)*69 -> 51681 | AW8: =ROUNDDOWN(MIN(AQ8,AU8)*0.5,0) -> 374 | BF8: =AV8+(AW8*3) -> 52803 | BG8: =AS8-BF8 -> 1125
E9: GC-X257CMHW.AEEPLMT | F9: Side-By-Side /SIZE : 22.4 คิว/ 635 ลิตร/ Plumbing/Smart Inverter Compressor | G9: PTOX257CMHW.APTO | H9: GC-X257CMHW.AEEPLMT | I9: REF3FILTER2.AETC | J9: 6M | K9: =1349+100 -> 1449 | L9: 60 | M9: =L9*K9 -> 86940 | P9: =MIN(K9,O9)*60 -> 86940 | Z9: =P9+(Q9*3) -> 86940 | AA9: =M9-Z9 -> 0 | AQ9: =1149+100 -> 1249 | AR9: 72 | AS9: =AR9*AQ9 -> 89928 | AV9: =MIN(AQ9,AU9)*72 -> 89928 | BF9: =AV9+(AW9*3) -> 89928 | BG9: =AS9-BF9 -> 0
E10: GV-V25FFGRB.ABMPLMT | F10: Multi-Door 21.6 คิว/ 612 ลิตร Smart Inverter Compressor | J10: 24M | K10: =949+50 -> 999 | L10: 60 | M10: =L10*K10 -> 59940 | P10: =MIN(K10,O10)*57 -> 56943 | Q10: =ROUNDDOWN(MIN(K10,O10)*0.5,0) -> 499 | Z10: =P10+(Q10*3) -> 58440 | AA10: =M10-Z10 -> 1500 | AQ10: =899+50 -> 949 | AR10: 72 | AS10: =AR10*AQ10 -> 68328 | AV10: =MIN(AQ10,AU10)*69 -> 65481 | AW10: =ROUNDDOWN(MIN(AQ10,AU10)*0.5,0) -> 474 | BF10: =AV10+(AW10*3) -> 66903 | BG10: =AS10-BF10 -> 1425
E11: GC-V22FFQMB.AEPPLMT | F11: Multi Door 18.7 Q/ 530 ลิตร | J11: 24M | K11: =849+50+50 -> 949 | L11: 60 | M11: =L11*K11 -> 56940 | P11: =MIN(K11,O11)*57 -> 54093 | R11: =ROUNDDOWN(MIN(K11,O11)*0.5,0) -> 474 | W11: 149 | Z11: =P11+(W11*1)+(R11*2) -> 55190 | AA11: =M11-Z11 -> 1750 | AQ11: =699+50+50 -> 799 | AR11: 72 | AS11: =AR11*AQ11 -> 57528 | AV11: =MIN(AQ11,AU11)*69 -> 55131 | AX11: =ROUNDDOWN(MIN(AQ11,AU11)*0.5,0) -> 399 | BC11: 149 | BF11: =AV11+(BC11*1)+(AX11*2) -> 56078 | BG11: =AS11-BF11 -> 1450
E12: GC-G24FFQKB.AEEPLM1 | F12: Multi Door 4D F/D Swing 22.5 คิว/ 637 ลิตร | J12: 24M | K12: =1299+50 -> 1349 | L12: 60 | M12: =L12*K12 -> 80940 | P12: =MIN(K12,O12)*57 -> 76893 | R12: =ROUNDDOWN(MIN(K12,O12)*0.5,0) -> 674 | W12: 149 | Z12: =P12+(W12*1)+(R12*2) -> 78390 | AA12: =M12-Z12 -> 2550 | AQ12: =1099+50 -> 1149 | AR12: 72 | AS12: =AR12*AQ12 -> 82728 | AV12: =MIN(AQ12,AU12)*69 -> 79281 | AX12: =ROUNDDOWN(MIN(AQ12,AU12)*0.5,0) -> 574 | BC12: 149 | BF12: =AV12+(BC12*1)+(AX12*2) -> 80578 | BG12: =AS12-BF12 -> 2150
E13: GC-X24FFCRB.AEVPLM1 | F13: Multi-Door 22.7 คิว/ 642 ลิตร Plumbing/Smart Inverter Compressor | G13: PTOX24FFCR2.APTO | H13: GC-X24FFCRB.AEVPLM1 | I13: REF3FILTER2.AETC | J13: 6M | K13: =1849-500+100 -> 1449 | L13: 60 | M13: =L13*K13 -> 86940 | P13: =MIN(K13,O13)*57 -> 82593 | X13: 149 | Z13: =P13+(X13*3) -> 83040 | AA13: =M13-Z13 -> 3900 | AQ13: =1649-500+100 -> 1249 | AR13: 72 | AS13: =AR13*AQ13 -> 89928 | AV13: =MIN(AQ13,AU13)*69 -> 86181 | BD13: 149 | BF13: =AV13+(BD13*3) -> 86628 | BG13: =AS13-BF13 -> 3300
E14: GC-L24FFCBB.AEVPLM1 | F14: Multi-Door 22.6 คิว/ 641 ลิตร/ Plumbing/Smart Inverter Compressor | G14: PTOL24FFCB2.APTO | H14: GC-L24FFCBB.AEVPLM1 | I14: REF3FILTER2.AETC | J14: 6M | K14: =1649-500+100 -> 1249 | L14: 60 | M14: =L14*K14 -> 74940 | P14: =MIN(K14,O14)*57 -> 71193 | X14: 149 | Z14: =P14+(X14*3) -> 71640 | AA14: =M14-Z14 -> 3300 | AQ14: =1449-500+100 -> 1049 | AR14: 72 | AS14: =AR14*AQ14 -> 75528 | AV14: =MIN(AQ14,AU14)*69 -> 72381 | BD14: 149 | BF14: =AV14+(BD14*3) -> 72828 | BG14: =AS14-BF14 -> 2700
E15: GN-F452PQAK.AEPPLMT | F15: 2 Doors | J15: 24M | K15: =549+50 -> 599 | L15: 60 | M15: =L15*K15 -> 35940 | P15: =MIN(K15,O15)*57 -> 34143 | Q15: =ROUNDDOWN(MIN(K15,O15)*0.5,0) -> 299 | Z15: =P15+(Q15*3) -> 35040 | AA15: =M15-Z15 -> 900 | AQ15: =449+50 -> 499 | AR15: 72 | AS15: =AR15*AQ15 -> 35928 | AV15: =MIN(AQ15,AU15)*69 -> 34431 | AW15: =ROUNDDOWN(MIN(AQ15,AU15)*0.5,0) -> 249 | BF15: =AV15+(AW15*3) -> 35178 | BG15: =AS15-BF15 -> 750
E16: GN-V389FQEF.AEPPLMT | F16: 2 Doors 12Q/ Bottom freezer Smart Inverter | J16: 24M | K16: 649 | L16: 60 | M16: =L16*K16 -> 38940 | P16: =MIN(K16,O16)*57 -> 36993 | Q16: =ROUNDDOWN(MIN(K16,O16)*0.5,0) -> 324 | Z16: =P16+(Q16*3) -> 37965 | AA16: =M16-Z16 -> 975 | AQ16: 549 | AR16: 72 | AS16: =AR16*AQ16 -> 39528 | AV16: =MIN(AQ16,AU16)*69 -> 37881 | AW16: =ROUNDDOWN(MIN(AQ16,AU16)*0.5,0) -> 274 | BF16: =AV16+(AW16*3) -> 38703 | BG16: =AS16-BF16 -> 825
D17: OBS Subs. | E17: GC-L257KQKW.AEPPLMT | F17: Side-By-Side/ 22.6 Q/ 641 ลิตร | J17: 24M | K17: =749+100-100 -> 749 | L17: 60 | M17: =L17*K17 -> 44940 | P17: =MIN(K17,O17)*60 -> 44940 | Z17: =P17+(Q17) -> 44940 | AA17: =M17-Z17 -> 0 | AQ17: =649+100-100 -> 649 | AR17: 72 | AS17: =AR17*AQ17 -> 46728 | AV17: =MIN(AQ17,AU17)*72 -> 46728 | BF17: =AV17+(AW17*3) -> 46728 | BG17: =AS17-BF17 -> 0
D18: OBS Subs | E18: GC-B257SQYL.AMCPLMT | F18: Side-By-Side/ 22.9 Q/ 649 ลิตร | J18: 24M | K18: =599-50 -> 549 | L18: 60 | M18: =L18*K18 -> 32940 | P18: =MIN(K18,O18)*60 -> 32940 | Z18: =P18+(Q18*3) -> 32940 | AA18: =M18-Z18 -> 0 | AQ18: =499-50 -> 449 | AR18: 72 | AS18: =AR18*AQ18 -> 32328 | AV18: =MIN(AQ18,AU18)*72 -> 32328 | BF18: =AV18+(AW18*3) -> 32328 | BG18: =AS18-BF18 -> 0
D19: OBS Subs. | E19: GV-B25FFGDB.ABMPLMT | F19: Multi-Door / 21.6 คิว / 611 ลิตร/ Black glass | J19: 24M | K19: =849-150 -> 699 | L19: 60 | M19: =L19*K19 -> 41940 | P19: =MIN(K19,O19)*60 -> 41940 | Z19: =P19+(V19*12) -> 41940 | AA19: =M19-Z19 -> 0 | AQ19: =699-100 -> 599 | AR19: 72 | AS19: =AR19*AQ19 -> 43128 | AV19: =MIN(AQ19,AU19)*72 -> 43128 | BF19: =AV19+(BB19*12) -> 43128 | BG19: =AS19-BF19 -> 0
D20: OBS Subs. | E20: GN-F392PQAK.AEPPLM1 | F20: 2 Doors Top Freezer | J20: 24M | K20: =499-50 -> 449 | L20: 60 | M20: =L20*K20 -> 26940 | P20: =MIN(K20,O20)*60 -> 26940 | Z20: =P20+(Q20*3) -> 26940 | AA20: =M20-Z20 -> 0 | AQ20: =399-50 -> 349 | AR20: 72 | AS20: =AR20*AQ20 -> 25128 | AV20: =MIN(AQ20,AU20)*72 -> 25128 | BF20: =AV20+(AW20) -> 25128 | BG20: =AS20-BF20 -> 0
C21: WM | E21: WT2520NHEG.ABGPETH | F21: Wash Tower 25 Kg (Green/Beige) | J21: 12M | K21: 2399 | L21: 60 | M21: =L21*K21 -> 143940 | P21: =MIN(K21,O21)*54 -> 129546 | Q21: =ROUNDDOWN(MIN(J21,N21)*0.5,0) -> 0 | S21: =ROUNDDOWN(MIN(K21,O21)*0.5,0) -> 1199 | W21: 149 | Z21: =P21+(W21*1)+(S21*5) -> 135690 | AA21: =M21-Z21 -> 8250 | AB21: 2199 | AC21: 60 | AD21: =AC21*AB21 -> 131940 | AG21: =MIN(AB21,AF21)*54 -> 118746 | AH21: =ROUNDDOWN((MIN(AB21,AF21)*0.5),0) -> 1099 | AL21: 149 | AO21: =(AB21*54)+(AL21*1)+(AH21*5) -> 124390 | AP21: =AD21-AO21 -> 7550 | AQ21: 2199 | AR21: 72 | AS21: =AR21*AQ21 -> 158328 | AV21: =MIN(AQ21,AU21)*66 -> 145134 | AY21: =ROUNDDOWN(MIN(AQ21,AU21)*0.5,0) -> 1099 | BC21: 149 | BF21: =AV21+(BC21*1)+(AY21*5) -> 150778 | BG21: =AS21-BF21 -> 7550 | BH21: 1999 | BI21: 72 | BJ21: =BI21*BH21 -> 143928 | BM21: =MIN(BH21,BL21)*66 -> 131934 | BN21: =ROUNDDOWN((MIN(BH21,BL21)*0.5),0) -> 999 | BR21: 149 | BU21: =BM21+(BR21*1)+(BN21*5) -> 137078 | BV21: =BJ21-BU21 -> 6850
E22: WT2520NHEN.ABNPETH | F22: Wash Tower 25 Kg (Navy/Beige) | J22: 12M | K22: 2399 | L22: 60 | M22: =L22*K22 -> 143940 | P22: =MIN(K22,O22)*54 -> 129546 | Q22: =ROUNDDOWN(MIN(J22,N22)*0.5,0) -> 0 | S22: =ROUNDDOWN(MIN(K22,O22)*0.5,0) -> 1199 | W22: 149 | Z22: =P22+(W22*1)+(S22*5) -> 135690 | AA22: =M22-Z22 -> 8250 | AB22: 2199 | AC22: 60 | AD22: =AC22*AB22 -> 131940 | AG22: =MIN(AB22,AF22)*54 -> 118746 | AH22: =ROUNDDOWN((MIN(AB22,AF22)*0.5),0) -> 1099 | AL22: 149 | AO22: =(AB22*54)+(AL22*1)+(AH22*5) -> 124390 | AP22: =AD22-AO22 -> 7550 | AQ22: 2199 | AR22: 72 | AS22: =AR22*AQ22 -> 158328 | AV22: =MIN(AQ22,AU22)*66 -> 145134 | AY22: =ROUNDDOWN(MIN(AQ22,AU22)*0.5,0) -> 1099 | BC22: 149 | BF22: =AV22+(BC22*1)+(AY22*5) -> 150778 | BG22: =AS22-BF22 -> 7550 | BH22: 1999 | BI22: 72 | BJ22: =BI22*BH22 -> 143928 | BM22: =MIN(BH22,BL22)*66 -> 131934 | BN22: =ROUNDDOWN((MIN(BH22,BL22)*0.5),0) -> 999 | BR22: 149 | BU22: =BM22+(BR22*1)+(BN22*5) -> 137078 | BV22: =BJ22-BU22 -> 6850
E23: WT2116SHEG.ABGPETH | F23: Wash Tower 21 Kg | J23: 12M | K23: 1999 | L23: 60 | M23: =L23*K23 -> 119940 | P23: =MIN(K23,O23)*54 -> 107946 | Q23: =ROUNDDOWN(MIN(J23,N23)*0.5,0) -> 0 | S23: =ROUNDDOWN(MIN(K23,O23)*0.5,0) -> 999 | W23: 149 | Z23: =P23+(W23*1)+(S23*5) -> 113090 | AA23: =M23-Z23 -> 6850 | AB23: 1899 | AC23: 60 | AD23: =AC23*AB23 -> 113940 | AG23: =MIN(AB23,AF23)*54 -> 102546 | AH23: =ROUNDDOWN((MIN(AB23,AF23)*0.5),0) -> 949 | AL23: 149 | AO23: =(AB23*54)+(AL23*1)+(AH23*5) -> 107440 | AP23: =AD23-AO23 -> 6500 | AQ23: 1749 | AR23: 72 | AS23: =AR23*AQ23 -> 125928 | AV23: =MIN(AQ23,AU23)*66 -> 115434 | AY23: =ROUNDDOWN(MIN(AQ23,AU23)*0.5,0) -> 874 | BC23: 149 | BF23: =AV23+(BC23*1)+(AY23*5) -> 119953 | BG23: =AS23-BF23 -> 5975 | BH23: 1649 | BI23: 72 | BJ23: =BI23*BH23 -> 118728 | BM23: =MIN(BH23,BL23)*66 -> 108834 | BN23: =ROUNDDOWN((MIN(BH23,BL23)*0.5),0) -> 824 | BR23: 149 | BU23: =BM23+(BR23*1)+(BN23*5) -> 113103 | BV23: =BJ23-BU23 -> 5625
E24: WT1410NHEG.ABGPQTH | F24: Wash Tower 14 Kg (Green/Beige) | J24: 12M | K24: 1599 | L24: 60 | M24: =L24*K24 -> 95940 | P24: =MIN(K24,O24)*54 -> 86346 | Q24: =ROUNDDOWN(MIN(J24,N24)*0.5,0) -> 0 | S24: =ROUNDDOWN(MIN(K24,O24)*0.5,0) -> 799 | W24: 149 | Z24: =P24+(W24*1)+(S24*5) -> 90490 | AA24: =M24-Z24 -> 5450 | AB24: 1499 | AC24: 60 | AD24: =AC24*AB24 -> 89940 | AG24: =MIN(AB24,AF24)*54 -> 80946 | AH24: =ROUNDDOWN((MIN(AB24,AF24)*0.5),0) -> 749 | AL24: 149 | AO24: =(AB24*54)+(AL24*1)+(AH24*5) -> 84840 | AP24: =AD24-AO24 -> 5100 | AQ24: 1399 | AR24: 72 | AS24: =AR24*AQ24 -> 100728 | AV24: =MIN(AQ24,AU24)*66 -> 92334 | AY24: =ROUNDDOWN(MIN(AQ24,AU24)*0.5,0) -> 699 | BC24: 149 | BF24: =AV24+(BC24*1)+(AY24*5) -> 95978 | BG24: =AS24-BF24 -> 4750 | BH24: 1299 | BI24: 72 | BJ24: =BI24*BH24 -> 93528 | BM24: =MIN(BH24,BL24)*66 -> 85734 | BN24: =ROUNDDOWN((MIN(BH24,BL24)*0.5),0) -> 649 | BR24: 149 | BU24: =BM24+(BR24*1)+(BN24*5) -> 89128 | BV24: =BJ24-BU24 -> 4400
E25: WT1410NHEN.ABNPQTH | F25: Wash Tower 14 Kg (Navy/Beige) | J25: 12M | K25: 1599 | L25: 60 | M25: =L25*K25 -> 95940 | P25: =MIN(K25,O25)*54 -> 86346 | Q25: =ROUNDDOWN(MIN(J25,N25)*0.5,0) -> 0 | S25: =ROUNDDOWN(MIN(K25,O25)*0.5,0) -> 799 | W25: 149 | Z25: =P25+(W25*1)+(S25*5) -> 90490 | AA25: =M25-Z25 -> 5450 | AB25: 1499 | AC25: 60 | AD25: =AC25*AB25 -> 89940 | AG25: =MIN(AB25,AF25)*54 -> 80946 | AH25: =ROUNDDOWN((MIN(AB25,AF25)*0.5),0) -> 749 | AL25: 149 | AO25: =(AB25*54)+(AL25*1)+(AH25*5) -> 84840 | AP25: =AD25-AO25 -> 5100 | AQ25: 1399 | AR25: 72 | AS25: =AR25*AQ25 -> 100728 | AV25: =MIN(AQ25,AU25)*66 -> 92334 | AY25: =ROUNDDOWN(MIN(AQ25,AU25)*0.5,0) -> 699 | BC25: 149 | BF25: =AV25+(BC25*1)+(AY25*5) -> 95978 | BG25: =AS25-BF25 -> 4750 | BH25: 1299 | BI25: 72 | BJ25: =BI25*BH25 -> 93528 | BM25: =MIN(BH25,BL25)*66 -> 85734 | BN25: =ROUNDDOWN((MIN(BH25,BL25)*0.5),0) -> 649 | BR25: 149 | BU25: =BM25+(BR25*1)+(BN25*5) -> 89128 | BV25: =BJ25-BU25 -> 4400
E26: F2520RNTB.AEBPETH | F26: Wash&Dry (Wash20 Kg.Dry 10 Kg) | J26: 12M | K26: 899 | L26: 60 | M26: =L26*K26 -> 53940 | P26: =MIN(K26,O26)*54 -> 48546 | Q26: =ROUNDDOWN(MIN(J26,N26)*0.5,0) -> 0 | T26: =ROUNDDOWN(MIN(K26,O26)*0.5,0) -> 449 | Z26: =P26+(T26*6) -> 51240 | AA26: =M26-Z26 -> 2700 | AB26: 849 | AC26: 60 | AD26: =AC26*AB26 -> 50940 | AG26: =MIN(AB26,AF26)*54 -> 45846 | AI26: =ROUNDDOWN((MIN(AB26,AF26)*0.5),0) -> 424 | AO26: =(AB26*54)+(AI26*6) -> 48390 | AP26: =AD26-AO26 -> 2550 | AQ26: 849 | AR26: 72 | AS26: =AR26*AQ26 -> 61128 | AV26: =MIN(AQ26,AU26)*66 -> 56034 | AZ26: =ROUNDDOWN(MIN(AQ26,AU26)*0.5,0) -> 424 | BF26: =AV26+(AZ26*6) -> 58578 | BG26: =AS26-BF26 -> 2550 | BH26: 799 | BI26: 72 | BJ26: =BI26*BH26 -> 57528 | BM26: =MIN(BH26,BL26)*72 -> 57528 | BO26: =ROUNDDOWN((MIN(BH26,BL26)*0.5),0) -> 399 | BU26: =(BH26*66)+(BO26*6) -> 55128 | BV26: =BJ26-BU26 -> 2400
E27: FV1413H4M.AMBPETH | F27: Wash&Dry (Wash13 Kg.Dry 8 Kg) | J27: 12M | K27: 749 | L27: 60 | M27: =L27*K27 -> 44940 | P27: =MIN(K27,O27)*57 -> 42693 | X27: 149 | Z27: =P27+(X27*3) -> 43140 | AA27: =M27-Z27 -> 1800 | AB27: 649 | AC27: 60 | AD27: =AC27*AB27 -> 38940 | AG27: =MIN(AB27,AF27)*57 -> 36993 | AM27: 149 | AO27: =AG27+(AM27*3) -> 37440 | AP27: =AD27-AO27 -> 1500 | AQ27: 649 | AR27: 72 | AS27: =AR27*AQ27 -> 46728 | AV27: =MIN(AQ27,AU27)*69 -> 44781 | BD27: 149 | BF27: =AV27+(BD27*3) -> 45228 | BG27: =AS27-BF27 -> 1500 | BH27: 599 | BI27: 72 | BJ27: =BI27*BH27 -> 43128 | BM27: =MIN(BH27,BL27)*69 -> 41331 | BS27: 149 | BU27: =BM27+(BS27*3) -> 41778 | BV27: =BJ27-BU27 -> 1350
E28: FV1413S4M.AMBPETH | F28: 13kg Wash Only | J28: 12M | K28: 699 | L28: 60 | M28: =L28*K28 -> 41940 | P28: =MIN(K28,O28)*54 -> 37746 | Q28: =ROUNDDOWN(MIN(J28,N28)*0.5,0) -> 0 | T28: =ROUNDDOWN(MIN(K28,O28)*0.5,0) -> 349 | Z28: =P28+(T28*6) -> 39840 | AA28: =M28-Z28 -> 2100 | AB28: 599 | AC28: 60 | AD28: =AC28*AB28 -> 35940 | AG28: =MIN(AB28,AF28)*54 -> 32346 | AI28: =ROUNDDOWN((MIN(AB28,AF28)*0.5),0) -> 299 | AO28: =(AB28*54)+(AI28*6) -> 34140 | AP28: =AD28-AO28 -> 1800 | AQ28: 599 | AR28: 72 | AS28: =AR28*AQ28 -> 43128 | AV28: =MIN(AQ28,AU28)*66 -> 39534 | AZ28: =ROUNDDOWN(MIN(AQ28,AU28)*0.5,0) -> 299 | BF28: =AV28+(AZ28*6) -> 41328 | BG28: =AS28-BF28 -> 1800 | BH28: 549 | BI28: 72 | BJ28: =BI28*BH28 -> 39528 | BM28: =MIN(BH28,BL28)*66 -> 36234 | BO28: =ROUNDDOWN((MIN(BH28,BL28)*0.5),0) -> 274 | BU28: =BM28+(BO28*6) -> 37878 | BV28: =BJ28-BU28 -> 1650
E29: TX2723ST5J.APBPETH | F29: T/L V+ 23kg | J29: 12M | K29: =549+50+50 -> 649 | L29: 60 | M29: =L29*K29 -> 38940 | P29: =MIN(K29,O29)*60 -> 38940 | Q29: =ROUNDDOWN(MIN(J29,N29)*0.5,0) -> 0 | Z29: =P29+(T29*6) -> 38940 | AA29: =M29-Z29 -> 0 | AB29: =499+50+50 -> 599 | AC29: 60 | AD29: =AC29*AB29 -> 35940 | AG29: =MIN(AB29,AF29)*60 -> 35940 | AO29: =(AB29*60)+(AI29*0) -> 35940 | AP29: =AD29-AO29 -> 0 | AQ29: =499+50+50 -> 599 | AR29: 72 | AS29: =AR29*AQ29 -> 43128 | AV29: =MIN(AQ29,AU29)*72 -> 43128 | BF29: =AV29+(AZ29*0) -> 43128 | BG29: =AS29-BF29 -> 0 | BH29: =449+50+50 -> 549 | BI29: 72 | BJ29: =BI29*BH29 -> 39528 | BM29: =MIN(BH29,BL29)*72 -> 39528 | BU29: =BM29+(BO29*6) -> 39528 | BV29: =BJ29-BU29 -> 0
E30: TX2315DT5G.DEGPETH | F30: T/L 15 Kg | J30: 12M | K30: =499+50 -> 549 | L30: 60 | M30: =L30*K30 -> 32940 | P30: =MIN(K30,O30)*60 -> 32940 | Z30: =P30 -> 32940 | AA30: =M30-Z30 -> 0 | AB30: =399+50 -> 449 | AC30: 60 | AD30: =AC30*AB30 -> 26940 | AG30: =MIN(AB30,AF30)*60 -> 26940 | AO30: =AG30+(AI30*6) -> 26940 | AP30: =AD30-AO30 -> 0 | AQ30: =399+50+50 -> 499 | AR30: 72 | AS30: =AR30*AQ30 -> 35928 | AV30: =MIN(AQ30,AU30)*72 -> 35928 | BF30: =AV30 -> 35928 | BG30: =AS30-BF30 -> 0 | BH30: =299+50+50 -> 399 | BI30: 72 | BJ30: =BI30*BH30 -> 28728 | BM30: =MIN(BH30,BL30)*72 -> 28728 | BU30: =BM30 -> 28728 | BV30: =BJ30-BU30 -> 0
D31: OBS Subs. | E31: FV1409H4W.ABWPETH | F31: Wash&Dry (Wash9 Kg.Dry 5Kg) | J31: 12M | K31: =499-100 -> 399 | L31: 60 | M31: =L31*K31 -> 23940 | P31: =MIN(K31,O31)*60 -> 23940 | Z31: =P31+(V31*60) -> 23940 | AA31: =M31-Z31 -> 0 | AB31: =449-100 -> 349 | AC31: 60 | AD31: =AC31*AB31 -> 20940 | AG31: =MIN(AB31,AF31)*60 -> 20940 | AO31: =AG31+(AK31*60) -> 20940 | AP31: =AD31-AO31 -> 0 | AQ31: =449-100 -> 349 | AR31: 72 | AS31: =AR31*AQ31 -> 25128 | AV31: =MIN(AQ31,AU31)*72 -> 25128 | BF31: =AV31+(BB31*72) -> 25128 | BG31: =AS31-BF31 -> 0 | BH31: =399-100 -> 299 | BI31: 72 | BJ31: =BI31*BH31 -> 21528 | BM31: =MIN(BH31,BL31)*72 -> 21528 | BU31: =BM31+(BQ31*72) -> 21528 | BV31: =BJ31-BU31 -> 0
D32: OBS Subs. | E32: TX2725AT9G.AEGPETH | F32: T/L LG AI DD™ Inverter 25kg | J32: 12M | K32: =649+50+50-100 -> 649 | L32: 60 | M32: =L32*K32 -> 38940 | P32: =MIN(K32,O32)*60 -> 38940 | Z32: =P32 -> 38940 | AA32: =M32-Z32 -> 0 | AB32: =599+50+50-100 -> 599 | AC32: 60 | AD32: =AC32*AB32 -> 35940 | AG32: =MIN(AB32,AF32)*60 -> 35940 | AO32: =AG32+(AI32*0) -> 35940 | AP32: =AD32-AO32 -> 0 | AQ32: =599+50+50-100 -> 599 | AR32: 72 | AS32: =AR32*AQ32 -> 43128 | AV32: =MIN(AQ32,AU32)*72 -> 43128 | BF32: =AV32 -> 43128 | BG32: =AS32-BF32 -> 0 | BH32: =549+50+50-100 -> 549 | BI32: 72 | BJ32: =BI32*BH32 -> 39528 | BM32: =MIN(BH32,BL32)*72 -> 39528 | BU32: =BM32 -> 39528 | BV32: =BJ32-BU32 -> 0
C33: Dryer | E33: RV10VHP4B.BMBPETH | F33: 10kg | J33: 12M | K33: 849 | L33: 60 | M33: =L33*K33 -> 50940 | P33: =MIN(K33,O33)*54 -> 45846 | Q33: =ROUNDDOWN(MIN(J33,N33)*0.5,0) -> 0 | T33: =ROUNDDOWN(MIN(K33,O33)*0.5,0) -> 424 | Z33: =P33+(T33*6) -> 48390 | AA33: =M33-Z33 -> 2550 | AB33: 749 | AC33: 60 | AD33: =AC33*AB33 -> 44940 | AG33: =MIN(AB33,AF33)*54 -> 40446 | AI33: =ROUNDDOWN((MIN(AB33,AF33)*0.5),0) -> 374 | AO33: =AG33+(AI33*6) -> 42690 | AP33: =AD33-AO33 -> 2250 | AQ33: 749 | AR33: 72 | AS33: =AR33*AQ33 -> 53928 | AV33: =MIN(AQ33,AU33)*66 -> 49434 | AZ33: =ROUNDDOWN(MIN(AQ33,AU33)*0.5,0) -> 374 | BF33: =AV33+(AZ33*6) -> 51678 | BG33: =AS33-BF33 -> 2250 | BH33: 649 | BI33: 72 | BJ33: =BI33*BH33 -> 46728 | BM33: =MIN(BH33,BL33)*66 -> 42834 | BO33: =ROUNDDOWN((MIN(BH33,BL33)*0.5),0) -> 324 | BU33: =BM33+(BO33*6) -> 44778 | BV33: =BJ33-BU33 -> 1950
C34: STYLER | E34: S3MFC.ALBPETH | F34: 3 Coat hangers | J34: 12M | Z34: =P34+(T34*6) -> 0 | AB34: 899 | AC34: 60 | AD34: =AC34*AB34 -> 53940 | AG34: =MIN(AB34,AF34)*48 -> 43152 | AJ34: =ROUNDDOWN((MIN(AB34,AF34)*0.5),0) -> 449 | AL34: 149 | AO34: =AG34+(AL34*1)+(AJ34*11) -> 48240 | AP34: =AD34-AO34 -> 5700 | BH34: 799 | BI34: 72 | BJ34: =BI34*BH34 -> 57528 | BM34: =MIN(BH34,BL34)*60 -> 47940 | BP34: =ROUNDDOWN((MIN(BH34,BL34)*0.5),0) -> 399 | BR34: 149 | BU34: =BM34+(BR34*1)+(BP34*11) -> 52478 | BV34: =BJ34-BU34 -> 5050
C35: DW | E35: DFC335HM.ABMPETH | F35: Dish Washer | J35: 12M | K35: 899 | L35: 60 | M35: =L35*K35 -> 53940 | P35: =MIN(K35,O35)*48 -> 43152 | U35: =ROUNDDOWN((MIN(K35,O35)*0.5),0) -> 449 | W35: 149 | Z35: =P35+(W35*1)+(U35*11) -> 48240 | AA35: =M35-Z35 -> 5700 | AB35: 849 | AC35: 60 | AD35: =AC35*AB35 -> 50940 | AG35: =MIN(AB35,AF35)*48 -> 40752 | AJ35: =ROUNDDOWN((MIN(AB35,AF35)*0.5),0) -> 424 | AL35: 149 | AO35: =AG35+(AL35*1)+(AJ35*11) -> 45565 | AP35: =AD35-AO35 -> 5375 | AQ35: 799 | AR35: 72 | AS35: =AR35*AQ35 -> 57528 | AV35: =MIN(AQ35,AU35)*60 -> 47940 | BA35: =ROUNDDOWN(MIN(AQ35,AU35)*0.5,0) -> 399 | BC35: 149 | BF35: =AV35+(BC35*1)+(BA35*11) -> 52478 | BG35: =AS35-BF35 -> 5050 | BH35: 749 | BI35: 72 | BJ35: =BI35*BH35 -> 53928 | BM35: =MIN(BH35,BL35)*60 -> 44940 | BP35: =ROUNDDOWN((MIN(BH35,BL35)*0.5),0) -> 374 | BR35: 149 | BU35: =BM35+(BR35*1)+(BP35*11) -> 49203 | BV35: =BJ35-BU35 -> 4725
E36: DFC533FV.APYPETH | F36: Dish Washer | J36: 12M | K36: 749 | L36: 60 | M36: =L36*K36 -> 44940 | P36: =MIN(K36,O36)*48 -> 35952 | U36: =ROUNDDOWN((MIN(K36,O36)*0.5),0) -> 374 | W36: 149 | Z36: =P36+(W36*1)+(U36*11) -> 40215 | AA36: =M36-Z36 -> 4725 | AB36: 699 | AC36: 60 | AD36: =AC36*AB36 -> 41940 | AG36: =MIN(AB36,AF36)*48 -> 33552 | AJ36: =ROUNDDOWN((MIN(AB36,AF36)*0.5),0) -> 349 | AL36: 149 | AO36: =AG36+(AL36*1)+(AJ36*11) -> 37540 | AP36: =AD36-AO36 -> 4400 | AQ36: 649 | AR36: 72 | AS36: =AR36*AQ36 -> 46728 | AV36: =MIN(AQ36,AU36)*60 -> 38940 | BA36: =ROUNDDOWN(MIN(AQ36,AU36)*0.5,0) -> 324 | BC36: 149 | BF36: =AV36+(BC36*1)+(BA36*11) -> 42653 | BG36: =AS36-BF36 -> 4075 | BH36: 599 | BI36: 72 | BJ36: =BI36*BH36 -> 43128 | BM36: =MIN(BH36,BL36)*60 -> 35940 | BP36: =ROUNDDOWN((MIN(BH36,BL36)*0.5),0) -> 299 | BR36: 149 | BU36: =BM36+(BR36*1)+(BP36*11) -> 39378 | BV36: =BJ36-BU36 -> 3750
C37: MWO | E37: MS4295DIS.BBKPETH | F37: Microwave 42 ลิตร | J37: NoService 6Y | K37: =59+10+20+10 -> 99 | M37: =K37*72 -> 7128

Sheet VCC, AP, Dehumidifier
E1: Promotion Price June 2026
F2: Service | G2: Subscription Fee
G3: Contract 5Y
G4: VISIT | S4: SELF
C5: Classification | D5: Model | F5: Service Cycle | G5: Visit 5Y Monthly price | H5: Total Month | I5: Normal total price | J5: Cost | K5: Promotion Jun | L5: Promotion | M5: Disc.50% (6 รอบบิล) | N5: Promotion Jun (3 รอบบิล) | O5: Promotion Jun (6 รอบบิล) | P5: Disc.50% (25 รอบบิล) | Q5: Promotion Net | R5: Disc from Normal | S5: Self 5Y Monthly price | T5: Total Month | U5: Normal total price | V5: Cost | W5: Promotion Jun | X5: Promotion | Y5: Disc.50% (3 รอบบิล) | Z5: Disc.50% (6 รอบบิล) | AA5: Promotion Jun (3 รอบบิล) | AB5: Promotion Jun (6 รอบบิล) | AC5: Disc.50% (25 รอบบิล) | AD5: Promotion Net | AE5: Disc from Normal
C6: VCC | D6: VCC | E6: A9T-ULTRA.DCBPETH | F6: 12M | I6: =H6*G6 -> 0 | L6: =MIN(G6,K6)*56 -> 0 | S6: =649+50+50 -> 749 | T6: 60 | U6: =T6*S6 -> 44940 | X6: =MIN(S6,W6)*57 -> 42693 | Y6: =ROUNDDOWN((MIN(S6,W6)*0.5),0) -> 374 | AD6: =X6+(Y6*3) -> 43815 | AE6: =U6-AD6 -> 1125
E7: A9T-LITE.DCGPETH | F7: 12M | I7: =H7*G7 -> 0 | L7: =MIN(G7,K7)*56 -> 0 | S7: =499+50 -> 549 | T7: 60 | U7: =T7*S7 -> 32940 | X7: =MIN(S7,W7)*60 -> 32940 | AD7: =X7+(AB7*60) -> 32940 | AE7: =U7-AD7 -> 0
C8: AP | D8: Air Purifier | E8: AS60GHWG0.ABAE | F8: 12M | G8: =549-100 -> 449 | H8: 60 | I8: =H8*G8 -> 26940 | L8: =MIN(G8,K8)*54 -> 24246 | M8: =ROUNDDOWN(MIN(G8,K8)*0.5,0) -> 224 | Q8: =L8+(M8*6) -> 25590 | R8: =I8-Q8 -> 1350 | S8: =499-100 -> 399 | T8: 60 | U8: =T8*S8 -> 23940 | X8: =MIN(S8,W8)*54 -> 21546 | Z8: =ROUNDDOWN((MIN(S8,W8)*0.5),0) -> 199 | AD8: =X8+(Z8*6) -> 22740 | AE8: =U8-AD8 -> 1200
E9: AS60GHWG0.ABAE | F9: 6M | G9: =599-100 -> 499 | H9: 60 | I9: =H9*G9 -> 29940 | L9: =MIN(G9,K9)*54 -> 26946 | M9: =ROUNDDOWN(MIN(G9,K9)*0.5,0) -> 249 | Q9: =L9+(M9*6) -> 28440 | R9: =I9-Q9 -> 1500 | S9: =549-100 -> 449 | T9: 60 | U9: =T9*S9 -> 26940 | X9: =MIN(S9,W9)*54 -> 24246 | Z9: =ROUNDDOWN((MIN(S9,W9)*0.5),0) -> 224 | AD9: =X9+(Z9*6) -> 25590 | AE9: =U9-AD9 -> 1350
E10: AS65GDBY0.ABAE | F10: 12M | G10: =849-100 -> 749 | H10: 60 | I10: =H10*G10 -> 44940 | L10: =MIN(G10,K10)*57 -> 42693 | N10: 149 | Q10: =L10+(N10*3) -> 43140 | R10: =I10-Q10 -> 1800 | S10: =799-100 -> 699 | T10: 60 | U10: =T10*S10 -> 41940 | X10: =MIN(S10,W10)*57 -> 39843 | AA10: 149 | AD10: =X10+(AA10*3) -> 40290 | AE10: =U10-AD10 -> 1650
E11: AS65GDBY0.ABAE | F11: 6M | G11: =899-100 -> 799 | H11: 60 | I11: =H11*G11 -> 47940 | L11: =MIN(G11,K11)*57 -> 45543 | N11: 149 | Q11: =L11+(N11*3) -> 45990 | R11: =I11-Q11 -> 1950 | S11: =849-100 -> 749 | T11: 60 | U11: =T11*S11 -> 44940 | X11: =MIN(S11,W11)*57 -> 42693 | AA11: 149 | AD11: =X11+(AA11*3) -> 43140 | AE11: =U11-AD11 -> 1800
E12: AS10GDBY0.ABAE | F12: 12M | G12: =1299-150 -> 1149 | H12: 60 | I12: =H12*G12 -> 68940 | L12: =MIN(G12,K12)*57 -> 65493 | N12: 149 | Q12: =L12+(N12*3) -> 65940 | R12: =I12-Q12 -> 3000 | S12: =1249-150 -> 1099 | T12: 60 | U12: =T12*S12 -> 65940 | X12: =MIN(S12,W12)*57 -> 62643 | AA12: 149 | AD12: =X12+(AA12*3) -> 63090 | AE12: =U12-AD12 -> 2850
E13: AS10GDBY0.ABAE | F13: 6M | G13: =1349-150 -> 1199 | H13: 60 | I13: =H13*G13 -> 71940 | L13: =MIN(G13,K13)*57 -> 68343 | N13: 149 | Q13: =L13+(N13*3) -> 68790 | R13: =I13-Q13 -> 3150 | S13: =1299-150 -> 1149 | T13: 60 | U13: =T13*S13 -> 68940 | X13: =MIN(S13,W13)*57 -> 65493 | AA13: 149 | AD13: =X13+(AA13*3) -> 65940 | AE13: =U13-AD13 -> 3000
E14: AS25GCBY0.ABAE | F14: 12M | G14: 599 | H14: 60 | I14: =H14*G14 -> 35940 | L14: =MIN(G14,K14)*54 -> 32346 | M14: =ROUNDDOWN(G14*0.5,0) -> 299 | Q14: =L14+(M14*6) -> 34140 | R14: =I14-Q14 -> 1800 | S14: 549 | T14: 60 | U14: =S14*60 -> 32940 | X14: =S14*54 -> 29646 | Z14: =ROUNDDOWN(S14*0.5,0) -> 274 | AD14: =X14+(Z14*6) -> 31290 | AE14: =U14-AD14 -> 1650
D15: OBS Subs. | E15: AS35GGW10.ATH | F15: 6M | G15: =349-50-50 -> 249 | H15: 60 | I15: =H15*G15 -> 14940 | L15: =MIN(G15,K15)*60 -> 14940 | Q15: =L15+(O15*60) -> 14940 | R15: =I15-Q15 -> 0 | S15: =299-50-50 -> 199 | T15: 60 | U15: =T15*S15 -> 11940 | X15: =MIN(S15,W15)*60 -> 11940 | AD15: =X15+(AB15*60) -> 11940 | AE15: =U15-AD15 -> 0
C16: Dehumidifier | E16: DD23GMWE1.ATH | F16: 12M | G16: 599 | H16: 60 | I16: =H16*G16 -> 35940 | L16: =MIN(G16,K16)*54 -> 32346 | O16: 149 | Q16: =L16+(O16*6) -> 33240 | R16: =I16-Q16 -> 2700 | S16: 549 | T16: 60 | U16: =S16*60 -> 32940 | X16: =S16*54 -> 29646 | AB16: 149 | AD16: =X16+(AB16*6) -> 30540 | AE16: =U16-AD16 -> 2400
D17: OBS Subs. | E17: MD19GQGA1.ATH | F17: 12M | G17: =549-100 -> 449 | H17: 60 | I17: =H17*G17 -> 26940 | L17: =MIN(G17,K17)*60 -> 26940 | Q17: =L17+(O17*6) -> 26940 | R17: =I17-Q17 -> 0 | S17: =499-100 -> 399 | T17: 60 | U17: =S17*60 -> 23940 | X17: =S17*60 -> 23940 | AD17: =X17+(AB17*6) -> 23940 | AE17: =U17-AD17 -> 0

Sheet RAC, SAC
E1: Promotion Price Jun 2026
L2: Service | M2: Subscription Fee
M3: Contract 5Y
C4: Classification | D4: Model | I4: PTO 1 | J4: PTO 2 | K4: PTO 3 | L4: Service Cycle | M4: Visit 5Y Monthly price | N4: Total Month | O4: Normal total price | P4: Cost | Q4: Promotion Jun | R4: Promotion | S4: Promotion Jun (1 รอบบิล) | T4: Disc.50% (5 รอบบิล) | U4: Disc.50% (6 รอบบิล) | V4: Disc.50% (12 รอบบิล) | W4: Promotion Net | X4: Disc from Normal
C5: RAC | E5: SAQ11A.S11 | F5: เบอร์ 5/Dual Cool /5 Star/WiFi | G5: SAQ11AN.S11 | H5: SAQ11AU.S11 | L5: 12M | M5: =749+50 -> 799 | N5: 60 | O5: =N5*M5 -> 47940 | R5: =MIN(M5,Q5)*54 -> 43146 | U5: =ROUNDDOWN(MIN(M5,Q5)*0.5,0) -> 399 | W5: =R5+(U5*6) -> 45540 | X5: =O5-W5 -> 2400
E6: SAQ11A.S11 | L6: 6M | M6: =849+50 -> 899 | N6: 60 | O6: =N6*M6 -> 53940 | R6: =MIN(M6,Q6)*54 -> 48546 | U6: =ROUNDDOWN(MIN(M6,Q6)*0.5,0) -> 449 | W6: =R6+(U6*6) -> 51240 | X6: =O6-W6 -> 2700
E7: SAQ13A.S11 | G7: SAQ13AN.S11 | H7: SAQ13AU.S11 | L7: 12M | M7: =799+50 -> 849 | N7: 60 | O7: =N7*M7 -> 50940 | R7: =MIN(M7,Q7)*54 -> 45846 | U7: =ROUNDDOWN(MIN(M7,Q7)*0.5,0) -> 424 | W7: =R7+(U7*6) -> 48390 | X7: =O7-W7 -> 2550
E8: SAQ13A.S11 | L8: 6M | M8: =899+50 -> 949 | N8: 60 | O8: =N8*M8 -> 56940 | R8: =MIN(M8,Q8)*54 -> 51246 | U8: =ROUNDDOWN(MIN(M8,Q8)*0.5,0) -> 474 | W8: =R8+(U8*6) -> 54090 | X8: =O8-W8 -> 2850
E9: SAQ18B.S21 | F9: เบอร์ 5/Dual Cool /4 Star/WiFi | G9: SAQ18BN.S21 | H9: SAQ18BU.S21 | L9: 12M | M9: =999+50 -> 1049 | N9: 60 | O9: =N9*M9 -> 62940 | R9: =MIN(M9,Q9)*54 -> 56646 | U9: =ROUNDDOWN(MIN(M9,Q9)*0.5,0) -> 524 | W9: =R9+(U9*6) -> 59790 | X9: =O9-W9 -> 3150
E10: SAQ18B.S21 | L10: 6M | M10: =1099+50 -> 1149 | N10: 60 | O10: =N10*M10 -> 68940 | R10: =MIN(M10,Q10)*54 -> 62046 | U10: =ROUNDDOWN(MIN(M10,Q10)*0.5,0) -> 574 | W10: =R10+(U10*6) -> 65490 | X10: =O10-W10 -> 3450
E11: SAQ24B.S21 | F11: เบอร์ 5/Dual Cool /3 Star/WiFi | G11: SAQ24BN.S21 | H11: SAQ24BU.S21 | L11: 12M | M11: 1199 | N11: 60 | O11: =N11*M11 -> 71940 | R11: =MIN(M11,Q11)*54 -> 64746 | U11: =ROUNDDOWN(MIN(M11,Q11)*0.5,0) -> 599 | W11: =R11+(U11*6) -> 68340 | X11: =O11-W11 -> 3600
E12: SAQ24B.S21 | L12: 6M | M12: 1299 | N12: 60 | O12: =N12*M12 -> 77940 | R12: =MIN(M12,Q12)*54 -> 70146 | U12: =ROUNDDOWN(MIN(M12,Q12)*0.5,0) -> 649 | W12: =R12+(U12*6) -> 74040 | X12: =O12-W12 -> 3900
E13: SIQ11B.S01 | F13: เบอร์ 5/Dual Cool /1 Star/WiFi | G13: SIQ11BN.S01 | H13: SIQ11BU.S01 | L13: 12M | M13: 599 | N13: 60 | O13: =N13*M13 -> 35940 | R13: =MIN(M13,Q13)*54 -> 32346 | U13: =ROUNDDOWN(MIN(M13,Q13)*0.5,0) -> 299 | W13: =R13+(U13*6) -> 34140 | X13: =O13-W13 -> 1800
E14: SIQ11B.S01 | L14: 6M | M14: 699 | N14: 60 | O14: =N14*M14 -> 41940 | R14: =MIN(M14,Q14)*54 -> 37746 | U14: =ROUNDDOWN(MIN(M14,Q14)*0.5,0) -> 349 | W14: =R14+(U14*6) -> 39840 | X14: =O14-W14 -> 2100
E15: SIQ13B.S01 | G15: SIQ13BN.S01 | H15: SIQ13BU.S01 | L15: 12M | M15: 699 | N15: 60 | O15: =N15*M15 -> 41940 | R15: =MIN(M15,Q15)*54 -> 37746 | U15: =ROUNDDOWN(MIN(M15,Q15)*0.5,0) -> 349 | W15: =R15+(U15*6) -> 39840 | X15: =O15-W15 -> 2100
E16: SIQ13B.S01 | L16: 6M | M16: 799 | N16: 60 | O16: =N16*M16 -> 47940 | R16: =MIN(M16,Q16)*54 -> 43146 | U16: =ROUNDDOWN(MIN(M16,Q16)*0.5,0) -> 399 | W16: =R16+(U16*6) -> 45540 | X16: =O16-W16 -> 2400
E17: SIQ18B.S11 | G17: SIQ18BN.S11 | H17: SIQ18BU.S11 | L17: 12M | M17: 899 | N17: 60 | O17: =N17*M17 -> 53940 | R17: =MIN(M17,Q17)*54 -> 48546 | U17: =ROUNDDOWN(MIN(M17,Q17)*0.5,0) -> 449 | W17: =R17+(U17*6) -> 51240 | X17: =O17-W17 -> 2700
E18: SIQ18B.S11 | L18: 6M | M18: 999 | N18: 60 | O18: =N18*M18 -> 59940 | R18: =MIN(M18,Q18)*54 -> 53946 | U18: =ROUNDDOWN(MIN(M18,Q18)*0.5,0) -> 499 | W18: =R18+(U18*6) -> 56940 | X18: =O18-W18 -> 3000
E19: SIQ24B.S11 | G19: SIQ24BN.S11 | H19: SIQ24BU.S11 | L19: 12M | M19: 1099 | N19: 60 | O19: =N19*M19 -> 65940 | R19: =MIN(M19,Q19)*54 -> 59346 | U19: =ROUNDDOWN(MIN(M19,Q19)*0.5,0) -> 549 | W19: =R19+(U19*6) -> 62640 | X19: =O19-W19 -> 3300
E20: SIQ24B.S11 | L20: 6M | M20: 1199 | N20: 60 | O20: =N20*M20 -> 71940 | R20: =MIN(M20,Q20)*54 -> 64746 | U20: =ROUNDDOWN(MIN(M20,Q20)*0.5,0) -> 599 | W20: =R20+(U20*6) -> 68340 | X20: =O20-W20 -> 3600
D21: New June ArtCool | E21: ART13A.SR1 | F21: Artcool | G21: ART13AN.SR1 | H21: ART13AU.SR1 | L21: 12M | M21: 949 | N21: 60 | O21: =N21*M21 -> 56940 | R21: =MIN(M21,Q21)*54 -> 51246 | S21: 149 | T21: =ROUNDDOWN(MIN(M21,Q21)*0.5,0) -> 474 | W21: =R21+(S21*1)+(T21*5) -> 53765 | X21: =O21-W21 -> 3175
E22: ART13A.SR1 | L22: 6M | M22: 1049 | N22: 60 | O22: =N22*M22 -> 62940 | R22: =MIN(M22,Q22)*54 -> 56646 | S22: 149 | T22: =ROUNDDOWN(MIN(M22,Q22)*0.5,0) -> 524 | W22: =R22+(S22*1)+(T22*5) -> 59415 | X22: =O22-W22 -> 3525
D23: New June ArtCool | E23: ART18A.SR1 | G23: ART18AN.SR1 | H23: ART18AU.SR1 | L23: 12M | M23: 1149 | N23: 60 | O23: =N23*M23 -> 68940 | R23: =MIN(M23,Q23)*54 -> 62046 | S23: 149 | T23: =ROUNDDOWN(MIN(M23,Q23)*0.5,0) -> 574 | W23: =R23+(S23*1)+(T23*5) -> 65065 | X23: =O23-W23 -> 3875
E24: ART18A.SR1 | L24: 6M | M24: 1249 | N24: 60 | O24: =N24*M24 -> 74940 | R24: =MIN(M24,Q24)*54 -> 67446 | S24: 149 | T24: =ROUNDDOWN(MIN(M24,Q24)*0.5,0) -> 624 | W24: =R24+(S24*1)+(T24*5) -> 70715 | X24: =O24-W24 -> 4225
D25: OBS Subs. | E25: IXY11A.JU1 | F25: เบอร์ 5/Dual Cool / 0 star/ Wifi | G25: IXY11AN.JU1 | H25: IXY11AU.JU1 | L25: 12M | M25: =499-100 -> 399 | N25: 60 | O25: =N25*M25 -> 23940 | R25: =MIN(M25,Q25)*60 -> 23940 | W25: =R25+(V25*60) -> 23940 | X25: =O25-W25 -> 0
E26: IXY11A.JU1 | L26: 6M | M26: =599-100 -> 499 | N26: 60 | O26: =N26*M26 -> 29940 | R26: =MIN(M26,Q26)*60 -> 29940 | W26: =R26+(V26*60) -> 29940 | X26: =O26-W26 -> 0
D27: OBS Subs. | E27: IXY13A.JU1 | G27: IXY13AN.JU1 | H27: IXY13AU.JU1 | L27: 12M | M27: =549-100 -> 449 | N27: 60 | O27: =N27*M27 -> 26940 | R27: =MIN(M27,Q27)*60 -> 26940 | W27: =R27+(V27*60) -> 26940 | X27: =O27-W27 -> 0
E28: IXY13A.JU1 | L28: 6M | M28: =649-100 -> 549 | N28: 60 | O28: =N28*M28 -> 32940 | R28: =MIN(M28,Q28)*60 -> 32940 | W28: =R28+(V28*60) -> 32940 | X28: =O28-W28 -> 0
D29: OBS Subs. | E29: IXY18A.KU1 | G29: IXY18AN.KU1 | H29: IXY18AU.KU1 | L29: 12M | M29: =749-150 -> 599 | N29: 60 | O29: =N29*M29 -> 35940 | R29: =MIN(M29,Q29)*60 -> 35940 | W29: =R29+(V29*60) -> 35940 | X29: =O29-W29 -> 0
E30: IXY18A.KU1 | L30: 6M | M30: =849-150 -> 699 | N30: 60 | O30: =N30*M30 -> 41940 | R30: =MIN(M30,Q30)*60 -> 41940 | W30: =R30+(V30*60) -> 41940 | X30: =O30-W30 -> 0
D31: OBS Subs. | E31: IXY24A.KU1 | G31: IXY24AN.KU1 | H31: IXY24AU.KU1 | L31: 12M | M31: =899-150 -> 749 | N31: 60 | O31: =N31*M31 -> 44940 | R31: =MIN(M31,Q31)*60 -> 44940 | W31: =R31+(V31*60) -> 44940 | X31: =O31-W31 -> 0
E32: IXY24A.KU1 | L32: 6M | M32: =999-150 -> 849 | N32: 60 | O32: =N32*M32 -> 50940 | R32: =MIN(M32,Q32)*60 -> 50940 | W32: =R32+(V32*60) -> 50940 | X32: =O32-W32 -> 0
C33: SAC | D33: Ceiling | E33: ZV-Q18GM1E0.EWGHATH | F33: Ceiling Type/ 17100 Btu | G33: ZVNQ18GM1E0.ENWTATH | H33: ZVUQ18GM1E0.EWGHATH | K33: PWFMDD200.ENCXLEU | L33: 4M | M33: =1399+100+100 -> 1599 | N33: 60 | O33: =N33*M33 -> 95940
D34: Cassette 4 Way | E34: ZT-Q18GPLE0.EWGHATH | F34: 4 Way | G34: ZTNQ18GPLE0.ENWHATH | H34: ZTUQ18GPLE0.EWGHATH | I34: PT-MPGW0.ENCXCOM | J34: PTAHMP0.ENCXCOM | K34: PWFMDD200.ENCXLEU | L34: 4M | M34: =1649+100+100+100 -> 1949 | N34: 60 | O34: =N34*M34 -> 116940
D35: Cassette 1 way | E35: ZT-Q12GULA0.EWGHATH | F35: 1 way | G35: ZTNQ12GULA0.ENWHATH | H35: ZTUQ12GULA0.EWGHATH | I35: PT-UPHG0.ENCXCOM | J35: PTAHTP0.ENCXCOM | K35: PWFMDD200.ENCXLEU | L35: 4M | M35: =1299+100+100 -> 1499 | N35: 60 | O35: =N35*M35 -> 89940
D36: Cassette Round | E36: ZT-Q48GYLA0.EWGHATH | F36: Round | G36: ZTNQ48GYLA0.ENWBATH | H36: ZTUQ48GYLA0.EWGHATH | J36: PTAHYP0.ENCXGLO | K36: PWFMDD200.ENCXLEU | L36: 4M | M36: =2499+100+100+100 -> 2799 | N36: 60 | O36: =N36*M36 -> 167940
K39: PWFMDD200.ENCXLEU -> PWFMDD202.ENCXCOM
H42: OUTRIGHT_SELF_2Y_B2B_SC ASSET

Sheet TV, MNT, AV
E1: Promotion Price Jun 2026
C2: Classification | D2: Model | G2: Contract | H2: Monthly fee | I2: Advance Payment 50% 12M | J2: Subscription Fee
J3: Montly fee | K3: Contract 5Y
J4: 1M-12M | K4: Service Cycle | L4: Total Month | M4: Normal total price | N4: Cost | O4: Promotion Jun | P4: 13M-60M (48) | Q4: 13M-15M (3) | R4: 16M-60M (45) | S4: 13M-18M (6) | T4: 19M-60M (42) | U4: 13M-24M (12) | V4: 13M-42M (30) | W4: 43M-60M (18) | X4: 25M-60M (36) | Y4: Promotion Net | Z4: Disc from Normal
C5: TV | E5: OLED77C6PSA.ATM | G5: 5 Y | H5: 1999 | I5: =J5*12 -> 11994 | J5: =H5*0.5 -> 999.5 | K5: No | L5: 60 | M5: =H5*L5 -> 119940 | O5: 13M~18M (6 Months 50% Discount) | S5: =ROUNDDOWN(H5*0.5,0) -> 999 | T5: =H5 -> 1999 | Y5: =I5+(J5*12)+(S5*6)+(T5*42) -> 113940 | Z5: =M5-Y5 -> 6000
E6: OLED65C6PSA.ATM | G6: 5 Y | H6: 1299 | I6: =J6*12 -> 7794 | J6: =H6*0.5 -> 649.5 | K6: No | L6: 60 | M6: =H6*L6 -> 77940 | O6: 13M~18M (6 Months 50% Discount) | S6: =ROUNDDOWN(H6*0.5,0) -> 649 | T6: =H6 -> 1299 | Y6: =I6+(J6*12)+(S6*6)+(T6*42) -> 74040 | Z6: =M6-Y6 -> 3900
E7: OLED55C6PSA.ATM | G7: 5 Y | H7: 1099 | I7: =J7*12 -> 6594 | J7: =H7*0.5 -> 549.5 | K7: No | L7: 60 | M7: =H7*L7 -> 65940 | O7: 13M~18M (6 Months 50% Discount) | S7: =ROUNDDOWN(H7*0.5,0) -> 549 | T7: =H7 -> 1099 | Y7: =I7+(J7*12)+(S7*6)+(T7*42) -> 62640 | Z7: =M7-Y7 -> 3300
D8: New June | E8: 100QNED86BS.ATM | F8: (W24 8-14/6) /ทีวี 100" LG QNED evo AI Mini LED QNED86 4K | G8: 5 Y | H8: 2599 | I8: =J8*12 -> 15594 | J8: =MIN(U8,H8)*50% -> 1299.5 | K8: No | L8: 60 | M8: =H8*L8 -> 155940 | O8: 13M~18M (6 Months 50% Discount) | S8: =ROUNDDOWN(H8*0.5,0) -> 1299 | T8: =H8 -> 2599 | Y8: =I8+(J8*12)+(S8*6)+(T8*42) -> 148140 | Z8: =M8-Y8 -> 7800
E9: 85QNED80BSA.ATM | G9: 5 Y | H9: 1349 | I9: =J9*12 -> 8094 | J9: =MIN(U9,H9)*50% -> 674.5 | K9: No | L9: 60 | M9: =H9*L9 -> 80940 | P9: =H9 -> 1349 | Y9: =I9+(J9*12)+(P9*48) -> 80940 | Z9: =M9-Y9 -> 0
E10: 65QNED80BSA.ATM | G10: 5 Y | H10: 649 | I10: =J10*12 -> 3894 | J10: =MIN(U10,H10)*50% -> 324.5 | K10: No | L10: 60 | M10: =H10*L10 -> 38940 | P10: =H10 -> 649 | Y10: =I10+(J10*12)+(P10*48) -> 38940 | Z10: =M10-Y10 -> 0
E11: 55QNED80BSA.ATM | G11: 5 Y | H11: 549 | I11: =J11*12 -> 3294 | J11: =MIN(U11,H11)*50% -> 274.5 | K11: No | L11: 60 | M11: =H11*L11 -> 32940 | P11: =H11 -> 549 | Y11: =I11+(J11*12)+(P11*48) -> 32940 | Z11: =M11-Y11 -> 0
D12: New June | E12: 75NU855BPSA.ATM | F12: (W24 8-14/6) | H12: 699 | I12: =J12*12 -> 4194 | J12: =MIN(U12,H12)*50% -> 349.5 | K12: No | L12: 60 | M12: =H12*L12 -> 41940 | P12: =H12 -> 699 | Y12: =I12+(J12*12)+(P12*48) -> 41940 | Z12: =M12-Y12 -> 0
E13: 65NU855BPSA.ATM | F13: (W17 20-26/4) | G13: 5 Y | H13: =499+50 -> 549 | I13: =J13*12 -> 3294 | J13: =MIN(U13,H13)*50% -> 274.5 | K13: No | L13: 60 | M13: =H13*L13 -> 32940 | P13: =H13 -> 549 | Y13: =I13+(J13*12)+(P13*48) -> 32940 | Z13: =M13-Y13 -> 0
E14: 27LX6TDGA.ATM | F14: Continue | G14: 5 Y | H14: =649+100 -> 749 | I14: =J14*12 -> 4494 | J14: =H14*0.5 -> 374.5 | K14: No | L14: 60 | M14: =H14*L14 -> 44940 | O14: 13M~24M (12 Months 50% Discount) | U14: =ROUNDDOWN(H14*0.5,0) -> 374 | X14: =H14 -> 749 | Y14: =I14+(J14*12)+(U14*12)+(X14*36) -> 40440 | Z14: =M14-Y14 -> 4500
D15: OBS Subs. | E15: OLED48C6PSA.ATM | G15: 5 Y | H15: =799-100 -> 699 | I15: =J15*12 -> 4194 | J15: =H15*0.5 -> 349.5 | K15: No | L15: 60 | M15: =H15*L15 -> 41940 | P15: =H15 -> 699 | Y15: =I15+(J15*12)+(P15*48) -> 41940 | Z15: =M15-Y15 -> 0
D16: OBS Subs. | E16: 75QNED86BSA.ATM | G16: 5 Y | H16: =999-150 -> 849 | I16: =J16*12 -> 5094 | J16: =MIN(U16,H16)*50% -> 424.5 | K16: No | L16: 60 | M16: =H16*L16 -> 50940 | P16: =H16 -> 849 | Y16: =I16+(J16*12)+(P16*48) -> 50940 | Z16: =M16-Y16 -> 0
C17: MNT | E17: 45GX950A-B.ATM | G17: 5Y | H17: =1399+100 -> 1499 | I17: =J17*12 -> 8994 | J17: =H17*0.5 -> 749.5 | K17: No | L17: 60 | M17: =H17*L17 -> 89940 | O17: 13M~18M (6 Months 50% Discount) | S17: =ROUNDDOWN(H17*0.5,0) -> 749 | T17: =H17 -> 1499 | Y17: =I17+(J17*12)+(S17*6)+(T17*42) -> 85440 | Z17: =M17-Y17 -> 4500
D18: New June | E18: 52G930B-B.ATM | G18: 5Y | H18: 1199 | I18: =J18*12 -> 7194 | J18: =H18*0.5 -> 599.5 | K18: No | L18: 60 | M18: =H18*L18 -> 71940 | O18: 13M~18M (6 Months 50% Discount) | S18: =ROUNDDOWN(H18*0.5,0) -> 599 | T18: =H18 -> 1199 | Y18: =I18+(J18*12)+(S18*6)+(T18*42) -> 68340 | Z18: =M18-Y18 -> 3600
D19: New June | E19: 40U990A-W.ATM | F19: W/in | G19: 5Y | H19: 999 | I19: =J19*12 -> 5994 | J19: =H19*0.5 -> 499.5 | K19: No | L19: 60 | M19: =H19*L19 -> 59940 | O19: 13M~18M (6 Months 50% Discount) | S19: =ROUNDDOWN(H19*0.5,0) -> 499 | T19: =H19 -> 999 | Y19: =I19+(J19*12)+(S19*6)+(T19*42) -> 56940 | Z19: =M19-Y19 -> 3000
E20: 32U889SA-W.ATM | G20: 5 Y | H20: =599+100 -> 699 | I20: =J20*12 -> 4194 | J20: =H20*0.5 -> 349.5 | K20: No | L20: 60 | M20: =H20*L20 -> 41940 | O20: 13M~24M (12 Months 50% Discount) | U20: =ROUNDDOWN(H20*0.5,0) -> 349 | X20: =H20 -> 699 | Y20: =I20+(J20*12)+(U20*12)+(X20*36) -> 37740 | Z20: =M20-Y20 -> 4200
E21: 34U650A-B.ATM | F21: (W13 | G21: 5 Y | H21: 399 | I21: =J21*12 -> 2394 | J21: =H21*0.5 -> 199.5 | K21: No | L21: 60 | M21: =H21*L21 -> 23940 | P21: =H21 -> 399 | Y21: =I21+(J21*12)+(P21*48) -> 23940 | Z21: =M21-Y21 -> 0
D22: OBS Subs. | E22: 27GX704A-B.ATM | G22: 5Y | H22: =449-100 -> 349 | I22: =J22*12 -> 2094 | J22: =MIN(U22,H22)*50% -> 174.5 | K22: No | L22: 60 | M22: =H22*L22 -> 20940 | O22: 13M~15M (3 Months 50% Discount) | Q22: =ROUNDDOWN(H22*0.5,0) -> 174 | R22: =H22 -> 349 | Y22: =I22+(J22*12)+(Q22*3)+(R22*45) -> 20415 | Z22: =M22-Y22 -> 525
C23: AV | E23: GRAB.ATHALBK | G23: 5 Y | H23: =79+20+10 -> 109 | I23: =J23*12 -> 654 | J23: =MIN(U23,H23)*50% -> 54.5 | K23: No | L23: 60 | M23: =H23*L23 -> 6540 | P23: =H23 -> 109 | Y23: =I23+(J23*12)+(P23*48) -> 6540 | Z23: =M23-Y23 -> 0
E24: BOUNCE.ATHALBK | G24: 5 Y | H24: =109+20+10 -> 139 | I24: =J24*12 -> 834 | J24: =MIN(U24,H24)*50% -> 69.5 | K24: No | L24: 60 | M24: =H24*L24 -> 8340 | P24: =H24 -> 139 | Y24: =I24+(J24*12)+(P24*48) -> 8340 | Z24: =M24-Y24 -> 0
E25: STAGE301.ATHALBK | G25: 5Y | H25: 299 | I25: =J25*12 -> 1794 | J25: =MIN(U25,H25)*50% -> 149.5 | K25: No | L25: 60 | M25: =H25*L25 -> 17940 | P25: =H25 -> 299 | Y25: =I25+(J25*12)+(P25*48) -> 17940 | Z25: =M25-Y25 -> 0
E26: S95TR.DTHALLK | G26: 5 Y | H26: =329+70+50 -> 449 | I26: =J26*12 -> 2694 | J26: =MIN(U26,H26)*50% -> 224.5 | K26: No | L26: 60 | M26: =H26*L26 -> 26940 | P26: =H26 -> 449 | Y26: =I26+(J26*12)+(P26*48) -> 26940 | Z26: =M26-Y26 -> 0
D27: Temporary Closed/ Supply W26 22/6 | E27: S70TY.ATHALLD | G27: 5 Y | H27: =159+10+20 -> 189 | I27: =J27*12 -> 1134 | J27: =MIN(U27,H27)*50% -> 94.5 | K27: No | L27: 60 | M27: =H27*L27 -> 11340 | P27: =H27 -> 189 | Y27: =I27+(J27*12)+(P27*48) -> 11340 | Z27: =M27-Y27 -> 0

Sheet 2606_RAW_All Channel
AQ1: =AVERAGE(AQ4:AQ183) -> 0.029616195
P2: As Is | AC2: To Be | BH2: To Be (August)
A3: Month | B3: Division | C3: Operation | D3: Model | G3: Exclusive Model | H3: Outright Price | I3: Contract (Year) | J3: Care Type | K3: Service Cycle (M) | L3: Original Price | M3: Original Total Price | N3: COI 2026 | O3: Sales (EA/Mon) | P3: As Is Price (THB) | Q3: Discount (THB) | R3: As Is Total Price (THB) | S3: COI | T3: Special Price | U3: Special Price Discount (Month) | V3: 50% Discount (Month) | W3: Total Promotion (THB) | X3: Total Promotion Price (THB) | Y3: Promotion % | Z3: vs Outright | AA3: COI Promotion | AB3: Bad Debt | AC3: To Be Price (THB) | AD3: Increase (To be - As Is) | AE3: Logic | AF3: To be Total Price (THB) | AG3: Increase Total Price (To be - As Is) | AH3: Special Price | AI3: COI | AJ3: Special Price 149THB/Month | AK3: 50% Discount (Month) | AL3: Total Promotion (THB) | AM3: Total Promotion Price (THB) | AN3: Promotion % | AO3: vs Outright | AP3: Increase (To be - As Is) | AQ3: Increase % (To be - As Is) | AR3: COI Promotion | AS3: Remark | AT3: Reflection | AU3: As Is Norma l - To be | AV3: Same | AW3: To Be Price (THB) | AX3: Increase (To be - As) | AY3: To be Total Price (THB) | AZ3: Special Price | BA3: 50% Discount (Month) | BB3: Total Promotion (THB) | BC3: Total Operation Price (THB) | BD3: Increase (To be - As) | BE3: Increase % (To be - As) | BF3: COI Promotion | BG3: Remark | BH3: To Be Price (THB) | BI3: To Be Price (THB) | BJ3: Increase (To be - As) | BK3: To be Total Price (THB) | BL3: Special Price | BM3: 50% Discount (Month) | BN3: Total Promotion (THB) | BO3: Total Operation Price (THB) | BP3: Increase (To be - As) | BQ3: Increase % (To be - As) | BR3: COI Promotion | BS3: Remark | BT3: Apr Sales | BW3: =IF(AA4>17%,AA4-2%,AA4) -> -0.10188921
A4: 2606 | B4: REF | C4: DST | D4: PTOX24FFCR2.APTO | E4: GC-X24FFCRB.AEVPLM1 | F4: REF3FILTER2.AETC | G4: =IFERROR(VLOOKUP(D4,[3]전용!E:J,6,0),"") | H4: 77666.667 | I4: 5 | J4: Visit | K4: 6 | L4: 1749 | M4: =L4*LEFT(I4,1)*12 -> 104940 | N4: 0.15 | P4: 1349 | Q4: =L4-P4 -> 400 | R4: =P4*LEFT(I4,1)*12 -> 80940 | S4: =AA4-(Y4/2) -> -0.089389211 | V4: 3 | W4: =(P4-T4)*U4+V4*P4*0.5 -> 2023.5 | X4: =R4-W4 -> 78916.5 | Y4: =X4/R4-1 -> -0.025 | Z4: =IFERROR(X4/H4,"") -> 1.0160923 | AA4: -0.10188921 | AB4: 0.0213149 | AC4: =P4+AD4 -> 1449 | AD4: 100 | AE4: =IF(AA4>10%,0,IF(AA4>5%,P4*0.04,IF(AA4>0%,P4*0.04, P4*0.1))) -> 134.9 | AF4: =AC4*LEFT(I4,1)*12 -> 86940 | AG4: =AF4/R4-1 -> 0.074128984 | AH4: 149 | AI4: =AR4+(AN4/2) -> -0.048192758 | AJ4: 3 | AK4: 0 | AL4: =(AC4-AH4)*AJ4+AK4*AC4*0.5 -> 3900 | AM4: =AF4-AL4 -> 83040 | AN4: =AM4/AF4-1 -> -0.044858523 | AO4: =IFERROR(AM4/H4,"") -> 1.0691845 | AP4: =AM4-X4 -> 4123.5 | AQ4: =AM4/X4-1 -> 0.05225143 | AR4: =IFERROR(AA4+AQ4*0.5,"")+5% -> -0.025763496 | AS4: Service Fee: 250 | BT4: {=vlook} -> #NAME? | BU4: =AP4/X4 -> 0.05225143 | BV4: 0.05 | BW4: =IF(AA4>19%,AA4-3.8%,AA4) -> -0.10188921
A5: 2606 | B5: REF | C5: DST | D5: PTOX24FFCR2.APTO | E5: GC-X24FFCRB.AEVPLM1 | F5: REF3FILTER2.AETC | G5: =IFERROR(VLOOKUP(D5,[3]전용!E:J,6,0),"") | H5: 77666.667 | I5: 6 | J5: Visit | K5: 6 | L5: 1549 | M5: =L5*LEFT(I5,1)*12 -> 111528 | N5: 0.15 | P5: 1149 | Q5: =L5-P5 -> 400 | R5: =P5*LEFT(I5,1)*12 -> 82728 | S5: =AA5-(Y5/2) -> -0.091472545 | V5: 3 | W5: =(P5-T5)*U5+V5*P5*0.5 -> 1723.5 | X5: =R5-W5 -> 81004.5 | Y5: =X5/R5-1 -> -0.020833333 | Z5: =IFERROR(X5/H5,"") -> 1.0429764 | AA5: -0.10188921 | AB5: 0.0213149 | AC5: =P5+AD5 -> 1249 | AD5: 100 | AE5: =IF(AA5>10%,0,IF(AA5>5%,P5*0.04,IF(AA5>0%,P5*0.04, P5*0.1))) -> 114.9 | AF5: =AC5*LEFT(I5,1)*12 -> 89928 | AG5: =AF5/R5-1 -> 0.087032202 | AH5: 149 | AI5: =AR5+(AN5/2) -> -0.035526189 | AJ5: 3 | AK5: 0 | AL5: =(AC5-AH5)*AJ5+AK5*AC5*0.5 -> 3300 | AM5: =AF5-AL5 -> 86628 | AN5: =AM5/AF5-1 -> -0.036696023 | AO5: =IFERROR(AM5/H5,"") -> 1.115382 | AP5: =AM5-X5 -> 5623.5 | AQ5: =AM5/X5-1 -> 0.069422069 | AR5: =IFERROR(AA5+AQ5*0.5,"")+5% -> -0.017178177 | AS5: Service Fee: 250 | BU5: =AP5/X5 -> 0.069422069 | BV5: 0.05 | BW5: =IF(AA5>19%,AA5-3.8%,AA5) -> -0.10188921
A6: 2606 | B6: REF | C6: EOL after inventory depletion | D6: PTOL24FFCB2.APTO | E6: GC-L24FFCBB.AEVPLM1 | F6: REF3FILTER2.AETC | G6: =IFERROR(VLOOKUP(D6,[3]전용!E:J,6,0),"") | H6: 62111.111 | I6: 5 | J6: Visit | K6: 6 | L6: 1549 | M6: =L6*LEFT(I6,1)*12 -> 92940 | N6: 0.15 | P6: 1149 | Q6: =L6-P6 -> 400 | R6: =P6*LEFT(I6,1)*12 -> 68940 | S6: =AA6-(Y6/2) -> -0.25137495 | V6: 3 | W6: =(P6-T6)*U6+V6*P6*0.5 -> 1723.5 | X6: =R6-W6 -> 67216.5 | Y6: =X6/R6-1 -> -0.025 | Z6: =IFERROR(X6/H6,"") -> 1.0821977 | AA6: -0.26387495 | AB6: 0.018432619 | AC6: =P6+AD6 -> 1249 | AD6: 100 | AE6: =IF(AA6>10%,0,IF(AA6>5%,P6*0.04,IF(AA6>0%,P6*0.04, P6*0.1))) -> 114.9 | AF6: =AC6*LEFT(I6,1)*12 -> 74940 | AG6: =AF6/R6-1 -> 0.087032202 | AH6: 149 | AI6: =AR6+(AN6/2) -> -0.11324478 | AJ6: 3 | AK6: 0 | AL6: =(AC6-AH6)*AJ6+AK6*AC6*0.5 -> 3300 | AM6: =AF6-AL6 -> 71640 | AN6: =AM6/AF6-1 -> -0.044035228 | AO6: =IFERROR(AM6/H6,"") -> 1.1534168 | AP6: =AM6-X6 -> 4423.5 | AQ6: =AM6/X6-1 -> 0.065809734 | AR6: =IFERROR(AA6+AQ6*0.8,"")+12% -> -0.091227167 | AS6: Service Fee: 200 | BU6: =AP6/X6 -> 0.065809734 | BV6: 0.03 | BW6: =IF(AA6>19%,AA6-3.8%,AA6) -> -0.26387495
A7: 2606 | B7: REF | C7: EOL after inventory depletion | D7: PTOL24FFCB2.APTO | E7: GC-L24FFCBB.AEVPLM1 | F7: REF3FILTER2.AETC | G7: =IFERROR(VLOOKUP(D7,[3]전용!E:J,6,0),"") | H7: 62111.111 | I7: 6 | J7: Visit | K7: 6 | L7: 1349 | M7: =L7*LEFT(I7,1)*12 -> 97128 | N7: 0.15 | P7: 949 | Q7: =L7-P7 -> 400 | R7: =P7*LEFT(I7,1)*12 -> 68328 | S7: =AA7-(Y7/2) -> -0.25345829 | V7: 3 | W7: =(P7-T7)*U7+V7*P7*0.5 -> 1423.5 | X7: =R7-W7 -> 66904.5 | Y7: =X7/R7-1 -> -0.020833333 | Z7: =IFERROR(X7/H7,"") -> 1.0771744 | AA7: -0.26387495 | AB7: 0.018432619 | AC7: =P7+AD7 -> 1049 | AD7: 100 | AE7: =IF(AA7>10%,0,IF(AA7>5%,P7*0.04,IF(AA7>0%,P7*0.04, P7*0.1))) -> 94.9 | AF7: =AC7*LEFT(I7,1)*12 -> 75528 | AG7: =AF7/R7-1 -> 0.10537408 | AH7: 149 | AI7: =AR7+(AN7/2) -> -0.1109198 | AJ7: 3 | AK7: 0 | AL7: =(AC7-AH7)*AJ7+AK7*AC7*0.5 -> 2700 | AM7: =AF7-AL7 -> 72828 | AN7: =AM7/AF7-1 -> -0.035748332 | AO7: =IFERROR(AM7/H7,"") -> 1.1725438 | AP7: =AM7-X7 -> 5923.5 | AQ7: =AM7/X7-1 -> 0.088536646 | AR7: =IFERROR(AA7+AQ7*0.8,"")+10% -> -0.093045638 | AS7: Service Fee: 200 | BU7: =AP7/X7 -> 0.088536646 | BV7: 0.03 | BW7: =IF(AA7>19%,AA7-3.8%,AA7) -> -0.26387495
A8: 2606 | B8: REF | C8: DST | D8: PTOV25FFGR3.APTO | E8: GV-V25FFGRB.ABMPLMT | G8: =IFERROR(VLOOKUP(D8,[3]전용!E:J,6,0),"") | H8: 53222.222 | I8: 5 | J8: Visit | K8: 24 | L8: 949 | M8: =L8*LEFT(I8,1)*12 -> 56940 | N8: 0.18477592 | P8: 949 | Q8: =L8-P8 -> 0 | R8: =P8*LEFT(I8,1)*12 -> 56940 | S8: =AA8-(Y8/2) -> -0.049170477 | V8: 6 | W8: =(P8-T8)*U8+V8*P8*0.5 -> 2847 | X8: =R8-W8 -> 54093 | Y8: =X8/R8-1 -> -0.05 | Z8: =IFERROR(X8/H8,"") -> 1.0163612 | AA8: -0.074170477 | AB8: 0.075190742 | AC8: =P8+AD8 -> 999 | AD8: 50 | AE8: =IF(AA8>10%,0,IF(AA8>5%,P8*0.04,IF(AA8>0%,P8*0.075, P8*0.1))) -> 94.9 | AF8: =AC8*LEFT(I8,1)*12 -> 59940 | AG8: =AF8/R8-1 -> 0.052687039 | AH8: 0 | AI8: =AR8+(AN8/2) -> -0.018436879 | AJ8: 0 | AK8: 3 | AL8: =(AC8-AH8)*AJ8+AK8*AC8*0.5 -> 1498.5 | AM8: =AF8-AL8 -> 58441.5 | AN8: =AM8/AF8-1 -> -0.025 | AO8: =IFERROR(AM8/H8,"") -> 1.0980658 | AP8: =AM8-X8 -> 4348.5 | AQ8: =AM8/X8-1 -> 0.080389329 | AR8: =IFERROR(AA8+AQ8*0.6,"")+2% -> -0.0059368794 | BU8: =AP8/X8 -> 0.080389329 | BV8: 0.01 | BW8: =IF(AA8>19%,AA8-3.8%,AA8) -> -0.074170477
A9: 2606 | B9: REF | C9: DST | D9: PTOV25FFGR3.APTO | E9: GV-V25FFGRB.ABMPLMT | G9: =IFERROR(VLOOKUP(D9,[3]전용!E:J,6,0),"") | H9: 53222.222 | I9: 6 | J9: Visit | K9: 24 | L9: 899 | M9: =L9*LEFT(I9,1)*12 -> 64728 | N9: 0.18477592 | P9: 899 | Q9: =L9-P9 -> 0 | R9: =P9*LEFT(I9,1)*12 -> 64728 | S9: =AA9-(Y9/2) -> -0.053337144 | V9: 6 | W9: =(P9-T9)*U9+V9*P9*0.5 -> 2697 | X9: =R9-W9 -> 62031 | Y9: =X9/R9-1 -> -0.041666667 | Z9: =IFERROR(X9/H9,"") -> 1.1655094 | AA9: -0.074170477 | AB9: 0.075190742 | AC9: =P9+AD9 -> 949 | AD9: 50 | AE9: =IF(AA9>10%,0,IF(AA9>5%,P9*0.04,IF(AA9>0%,P9*0.075, P9*0.1))) -> 89.9 | AF9: =AC9*LEFT(I9,1)*12 -> 68328 | AG9: =AF9/R9-1 -> 0.055617353 | AH9: 0 | AI9: =AR9+(AN9/2) -> -0.01744781 | AJ9: 0 | AK9: 3 | AL9: =(AC9-AH9)*AJ9+AK9*AC9*0.5 -> 1423.5 | AM9: =AF9-AL9 -> 66904.5 | AN9: =AM9/AF9-1 -> -0.020833333 | AO9: =IFERROR(AM9/H9,"") -> 1.2570783 | AP9: =AM9-X9 -> 4873.5 | AQ9: =AM9/X9-1 -> 0.078565556 | AR9: =IFERROR(AA9+AQ9*0.6,"")+2% -> -0.0070311436 | BU9: =AP9/X9 -> 0.078565556 | BV9: 0.01 | BW9: =IF(AA9>19%,AA9-3.8%,AA9) -> -0.074170477
A10: 2606 | B10: REF | C10: DST | D10: GC-G24FFQKB.AEEPLM1 | G10: =IFERROR(VLOOKUP(D10,[3]전용!E:J,6,0),"") | H10: 61000 | I10: 5 | J10: Visit | K10: 24 | L10: 1299 | M10: =L10*LEFT(I10,1)*12 -> 77940 | N10: 0.17841392 | P10: 1299 | Q10: =L10-P10 -> 0 | R10: =P10*LEFT(I10,1)*12 -> 77940 | S10: =AA10-(Y10/2) -> 0.081027598 | V10: 6 | W10: =(P10-T10)*U10+V10*P10*0.5 -> 3897 | X10: =R10-W10 -> 74043 | Y10: =X10/R10-1 -> -0.05 | Z10: =IFERROR(X10/H10,"") -> 1.2138197 | AA10: 0.056027598 | AB10: 0.036888813 | AC10: =P10+AD10 -> 1349 | AD10: 50 | AE10: =IF(AA10>10%,0,IF(AA10>5%,P10*0.04,IF(AA10>0%,P10*0.075, P10*0.1))) -> 51.96 | AF10: =AC10*LEFT(I10,1)*12 -> 80940 | AG10: =AF10/R10-1 -> 0.038491147 | AH10: 0 | AI10: =AR10+(AN10/2) -> 0.076437528 | AJ10: 0 | AK10: 3 | AL10: =(AC10-AH10)*AJ10+AK10*AC10*0.5 -> 2023.5 | AM10: =AF10-AL10 -> 78916.5 | AN10: =AM10/AF10-1 -> -0.025 | AO10: =IFERROR(AM10/H10,"") -> 1.2937131 | AP10: =AM10-X10 -> 4873.5 | AQ10: =AM10/X10-1 -> 0.065819861 | AR10: =IFERROR(AA10+AQ10*0.5,"") -> 0.088937528 | BU10: =AP10/X10 -> 0.065819861 | BV10: 0.087150387 | BW10: =IF(AA10>19%,AA10-3.8%,AA10) -> 0.056027598
A11: 2606 | B11: REF | C11: DST | D11: GC-G24FFQKB.AEEPLM1 | G11: =IFERROR(VLOOKUP(D11,[3]전용!E:J,6,0),"") | H11: 61000 | I11: 6 | J11: Visit | K11: 24 | L11: 1099 | M11: =L11*LEFT(I11,1)*12 -> 79128 | N11: 0.17926517 | P11: 1099 | Q11: =L11-P11 -> 0 | R11: =P11*LEFT(I11,1)*12 -> 79128 | S11: =AA11-(Y11/2) -> 0.076860931 | V11: 6 | W11: =(P11-T11)*U11+V11*P11*0.5 -> 3297 | X11: =R11-W11 -> 75831 | Y11: =X11/R11-1 -> -0.041666667 | Z11: =IFERROR(X11/H11,"") -> 1.2431311 | AA11: 0.056027598 | AB11: 0.036888813 | AC11: =P11+AD11 -> 1149 | AD11: 50 | AE11: =IF(AA11>10%,0,IF(AA11>5%,P11*0.04,IF(AA11>0%,P11*0.075, P11*0.1))) -> 43.96 | AF11: =AC11*LEFT(I11,1)*12 -> 82728 | AG11: =AF11/R11-1 -> 0.045495905 | AH11: 0 | AI11: =AR11+(AN11/2) -> 0.07972297 | AJ11: 0 | AK11: 3 | AL11: =(AC11-AH11)*AJ11+AK11*AC11*0.5 -> 1723.5 | AM11: =AF11-AL11 -> 81004.5 | AN11: =AM11/AF11-1 -> -0.020833333 | AO11: =IFERROR(AM11/H11,"") -> 1.3279426 | AP11: =AM11-X11 -> 5173.5 | AQ11: =AM11/X11-1 -> 0.068224077 | AR11: =IFERROR(AA11+AQ11*0.5,"") -> 0.090139636 | BU11: =AP11/X11 -> 0.068224077 | BV11: 0.057150387 | BW11: =IF(AA11>19%,AA11-3.8%,AA11) -> 0.056027598
